Workbook

Sheet Summary
A1: DIY Mini-Airboat — BOM summary (riveted aluminum hull)
A2: Totals pull from the three BOM tabs. Change quantities, prices or weights there; change the contingency in B11.
A4: Group | B4: Est. cost ($) | C4: Weight (lb) | D4: Weight in CAD (lb) | E4: Weight not in CAD (lb)
A5: Hull | B5: =Hull!F25 -> 5040 | C5: =Hull!G25 -> 347.5 | D5: =Hull!G26 -> 330.5 | E5: =Hull!G27 -> 17
A6: Drivetrain | B6: =Drivetrain!F41 -> 6038 | C6: =Drivetrain!G41 -> 389.4 | D6: =Drivetrain!G42 -> 385.4 | E6: =Drivetrain!G43 -> 4
A7: Everything else | B7: ='Everything else'!F61 -> 5154 | C7: ='Everything else'!G61 -> 331.9 | D7: ='Everything else'!G62 -> 322.9 | E7: ='Everything else'!G63 -> 9
A8: Subtotal | B8: =SUM(B5:B7) -> 16232 | C8: =SUM(C5:C7) -> 1068.8 | D8: =SUM(D5:D7) -> 1038.8 | E8: =SUM(E5:E7) -> 30
A10: Contingency (shipping, tax, mistakes, extras) | B10: =B8*B11 -> 2434.8
A11: Contingency rate | B11: 0.15 | C11: Assumption: 15% of materials; edit as needed
A12: Estimated materials total | B12: =B8+B10 -> 18666.8
A14: Weight check
A15: Empty boat, CAD model (no fuel or crew) | B15: 1038.8 | C15: lb, from the final trim analysis
A16: BOM weight in CAD (should match) | B16: =D8 -> 1038.8
A17: Difference | B17: =B16-B15 -> 0
A18: Empty boat incl. items not in CAD | B18: =C8 -> 1068.8
A20: Labor and the fab shop shear/brake service are not included here; see DIY-Mini-Airboat_Build-Guide_Aluminum.xlsx.
A21: Supplier links appear only where a supplier was discussed during design.

Sheet Hull
A1: DIY Mini-Airboat — Hull BOM (riveted aluminum)
A2: Costs are 2026 USD estimates. Blue cells are inputs you can change; Est. cost = Qty x Unit cost. Weight is the installed line weight in lb.
A4: Item | B4: Use / spec | C4: Qty | D4: Unit | E4: Unit cost ($) | F4: Est. cost ($) | G4: Weight (lb) | H4: In CAD weight? | I4: Supplier link | J4: Notes
A5: 5052-H32 aluminum sheet 0.090 in, 60 x 144 in | B5: Bottom halves with the 3 in chine bent in, bow rocker pieces, bow face | C5: 3 | D5: sheet | E5: 450 | F5: =C5*E5 -> 1350 | G5: 97.6 | H5: Y | J5: Centerline seam over the center stringer; transverse butt seam with doubler at frame 120
A6: 5052-H32 aluminum sheet 0.063 in, 48 x 144 in | B6: Side panels | C6: 2 | D6: sheet | E6: 230 | F6: =C6*E6 -> 460 | G6: 22 | H6: Y
A7: 5052-H32 aluminum sheet 0.125 in, 24 x 72 in | B7: Transom | C7: 1 | D7: sheet | E7: 180 | F7: =C7*E7 -> 180 | G7: 14.5 | H7: Y
A8: 5052 strip 0.080 and 0.063 in, brake-formed into hat sections | B8: 5 stringers, 2.5 in tall (0.080 for the two engine-bed stringers); 1 in cross-drain slot in each at x 3.5-4.5 | C8: 1 | D8: lot | E8: 350 | F8: =C8*E8 -> 350 | G8: 39.4 | H8: Y | J8: Bend to the rocker before riveting
A9: 6061 angle 1-1/2 x 1-1/2 x 1/8 in, 12 ft | B9: 7 frames + transom frame | C9: 5 | D9: stick | E9: 42 | F9: =C9*E9 -> 210 | G9: 24.8 | H9: Y | J9: 1 x 3/4 in limber notch at the skin in every bay of every frame; deburr and prime the cut edges
A10: 6061 rectangular tube 2 x 3 x 1/8 in, 12 ft | B10: Engine-bed box beams on the bed stringers | C10: 1 | D10: stick | E10: 95 | F10: =C10*E10 -> 95 | G10: 12.9 | H10: Y
A11: 6061 angle 1 x 1 x 1/8 in, 12 ft | B11: Rub rails / sheer clamps | C11: 3 | D11: stick | E11: 25 | F11: =C11*E11 -> 75 | G11: 6.4 | H11: Y
A12: 6061 plate 1/4 in | B12: Quarter knees and frame-12 gussets under the cage plates | C12: 1 | D12: lot | E12: 40 | F12: =C12*E12 -> 40 | G12: 3.6 | H12: Y
A13: 6061 aluminum 1/4 in flat bar and plate | B13: Engine bed plates 48 x 3 in (2), cage mount plates 4 x 4 in (4) | C13: 1 | D13: lot | E13: 130 | F13: =C13*E13 -> 130 | G13: 8.4 | H13: Y | J13: Drill beds 16 x 13/32 in at 3 in spacing
A14: HDPE sheet 1/8 in, 12 x 24 in | B14: Isolator strips under all aluminum plates | C14: 1 | D14: sheet | E14: 25 | F14: =C14*E14 -> 25 | G14: 1.5 | H14: Y
A15: 6061 angle 1-1/2 x 1-1/2 x 1/8 in (2) + 5052 sheet 1/8 in for nose cap | B15: Chine guard angles opened to 135 deg; bent nose cap | C15: 1 | D15: lot | E15: 120 | F15: =C15*E15 -> 120 | G15: 15.9 | H15: Y
A16: UHMW 1/4 in sheet, 48 x 120 in | B16: 4 bottom strips (splice over a frame) | C16: 3 | D16: sheet | E16: 290 | F16: =C16*E16 -> 870 | G16: 82.8 | H16: Y | J16: 3/16 in saves about 21 lb
A17: Closed-end aluminum blind rivets 3/16 in (5052/5056, aluminum mandrel) | B17: All skin laps and framing; double rows at about 3/4 in | C17: 2500 | D17: ea | E17: 0.15 | F17: =C17*E17 -> 375 | G17: 5 | H17: N | J17: Never open-end or steel-mandrel rivets
A18: Seam sealant (Sikaflex 291 or 3M 4200), 10 oz tubes | B18: Wet in every lap before riveting | C18: 10 | D18: tube | E18: 15 | F18: =C18*E18 -> 150 | G18: 4 | H18: N
A19: SS 1/4 in through-bolts, nylock nuts, sealing washers | B19: UHMW strips through the bottom into the stringers | C19: 200 | D19: set | E19: 0.8 | F19: =C19*E19 -> 160 | G19: 3 | H19: N | J19: Bed in sealant; Tef-Gel on threads
A20: Clecos 3/16 in (100) + pliers, drill bits, deburr tools | B20: Tooling | C20: 1 | D20: lot | E20: 150 | F20: =C20*E20 -> 150 | G20: 0 | H20: N
A21: Self-etching primer + marine topcoat (olive drab) | B21: Inside and out | C21: 1 | D21: lot | E21: 260 | F21: =C21*E21 -> 260 | G21: 5 | H21: N
A22: Rev 6 joint details
A23: Bed plates lengthened to 52 in, new 10-hole pattern; knees/gussets drilled for cage-foot bolts | B23: Net change from the detailed hull model | C23: 1 | D23: lot | E23: 40 | F23: =C23*E23 -> 40 | G23: 0.7 | H23: Y | J23: Hole positions in the fab workbook
A25: Total | F25: =SUM(F5:F23) -> 5040 | G25: =SUM(G5:G23) -> 347.5
A26: Weight included in the CAD model | G26: =SUMIF(H5:H23,"Y",G5:G23) -> 330.5
A27: Weight not in the CAD model (fasteners, paint, wiring) | G27: =SUMIF(H5:H23,"N",G5:G23) -> 17
A28: CAD model weight for this group (reference) | G28: 330.5 | J28: From the CAD weight reports (hull r4.2, drivetrain r5, layout r6 + cage r2 + flotation r5)

Sheet Drivetrain
A1: DIY Mini-Airboat — Drivetrain BOM
A2: Costs are 2026 USD estimates. Blue cells are inputs you can change; Est. cost = Qty x Unit cost. Weight is the installed line weight in lb.
A4: Item | B4: Use / spec | C4: Qty | D4: Unit | E4: Unit cost ($) | F4: Est. cost ($) | G4: Weight (lb) | H4: In CAD weight? | I4: Supplier link | J4: Notes
A5: Suzuki G13 1.3 L engine (junkyard), dressed | B5: 1995-2001 Geo/Chevy Metro 1.3 or Suzuki Swift; with flywheel, starter, alternator, intake, ECU/harness | C5: 1 | D5: ea | E5: 600 | F5: =C5*E5 -> 600 | G5: 179 | H5: Y | I5: https://www.car-part.com | J5: Weight is the CAD placeholder: verify on a scale
A6: Engine refresh kit | B6: Gaskets, timing belt + tensioner, water pump, plugs, thermostat, oil and filter | C6: 1 | D6: kit | E6: 320 | F6: =C6*E6 -> 320 | G6: 0 | H6: N
A7: Fuel delivery | B7: Electric pump, filter, fuel line, primer bulb, clamps | C7: 1 | D7: lot | E7: 140 | F7: =C7*E7 -> 140 | G7: 3 | H7: N
A8: Bellhousing adapter | B8: 3/8 in 6061 plate + shroud, machined to the G13 pattern, starter boss | C8: 1 | D8: ea | E8: 160 | F8: =C8*E8 -> 160 | G8: 11 | H8: Y | J8: Material + DIY machining; pattern from the real block
A9: Flex coupling (jaw or donut type) | B9: Torsional damper, flywheel to jackshaft; rated 150 lb-ft or more | C9: 1 | D9: ea | E9: 130 | F9: =C9*E9 -> 130 | G9: 1.3 | H9: Y
A10: Jackshaft 1-1/4 in 4140 + 2 bearings + housing | B10: Takes belt pull off the crankshaft | C10: 1 | D10: lot | E10: 170 | F10: =C10*E10 -> 170 | G10: 4.4 | H10: Y
A11: HTD 8M pulley, 30 teeth, 85 mm, taper-lock + bushing | B11: Drive pulley on jackshaft | C11: 1 | D11: ea | E11: 140 | F11: =C11*E11 -> 140 | G11: 5.7 | H11: Y
A12: HTD 8M pulley, 75 teeth, 85 mm, aluminum, taper-lock + bushing | B12: Prop pulley between the bearings | C12: 1 | D12: ea | E12: 330 | F12: =C12*E12 -> 330 | G12: 7.5 | H12: Y
A13: HTD belt 2320-8M-85 (290 teeth) | B13: Gates PowerGrip HTD or equal; 2.5 : 1 | C13: 1 | D13: ea | E13: 190 | F13: =C13*E13 -> 190 | G13: 3 | H13: Y | J13: Confirm width with Gates design data for 74 lb-ft
A14: Backside idler 3.5 in + bearing + pad bracket (optional) | B14: Slack-side idler bolted to adapter | C14: 1 | D14: ea | E14: 70 | F14: =C14*E14 -> 70 | G14: 3.2 | H14: Y | J14: Fit only if ground runs show belt flap
A15: Prop shaft 1-1/2 in 4140, 20 in, keyed | B15: Supported fore and aft | C15: 1 | D15: ea | E15: 110 | F15: =C15*E15 -> 110 | G15: 9.8 | H15: Y
A16: Flange bearing 1-1/2 in, 4-bolt | B16: One in each yoke plate | C16: 2 | D16: ea | E16: 55 | F16: =C16*E16 -> 110 | G16: 9 | H16: Y
A17: Prop flange / hub adapter | B17: Machined to the Warp Drive HPL hub pattern | C17: 1 | D17: ea | E17: 140 | F17: =C17*E17 -> 140 | G17: 3.8 | H17: Y
A18: Tension yoke: 3/8 in 6061 plates + 1 in tie tubes | B18: Carries both bearings; pivots as one piece | C18: 1 | D18: lot | E18: 170 | F18: =C18*E18 -> 170 | G18: 13.3 | H18: Y
A19: 1/2 in grade 8 bolts + lock nuts; 1/2-13 jack screw + block | B19: Pivot (2), arc slot (4), jack screw | C19: 1 | D19: lot | E19: 45 | F19: =C19*E19 -> 45 | G19: 2 | H19: Y
A20: 6061 square tube 2 x 2 x 1/8 in | B20: A-frame legs and crossbars | C20: 30 | D20: ft | E20: 9 | F20: =C20*E20 -> 270 | G20: 17.8 | H20: Y
A21: 6061 plate 3/8 in, 24 x 30 in | B21: Two gusset-shaped peak plates with lightening holes | C21: 1 | D21: ea | E21: 210 | F21: =C21*E21 -> 210 | G21: 20 | H21: Y
A22: 6061 plate 1/4 in | B22: A-frame and brace feet (6) | C22: 1 | D22: lot | E22: 40 | F22: =C22*E22 -> 40 | G22: 2.6 | H22: Y
A23: 6061 tube 1-1/2 x 1-1/2 x 1/8 and 1 x 1 in | B23: Diagonal braces (2) and adapter tie struts (2) | C23: 16 | D23: ft | E23: 8 | F23: =C23*E23 -> 128 | G23: 7.1 | H23: Y
A24: Engine mount: steel bracket + polyurethane bushing | B24: Bolted to engine-bed plates at x = 30 and 42 in | C24: 4 | D24: ea | E24: 35 | F24: =C24*E24 -> 140 | G24: 15.3 | H24: Y
A25: Warp Drive 64R-TX-HPL3 propeller | B25: 64 in, 3 carbon blades, HPL hub, ground-adjustable, R rotation | C25: 1 | D25: ea | E25: 1395 | F25: =C25*E25 -> 1395 | G25: 18 | H25: Y | I25: https://warpdriveinc.com/product/3-bld-prop-hpl-hub/ | J25: Price from Warp Drive page; confirm rotation, hub pattern and weight before ordering
A26: Leading-edge protection tape (stoneguard) | B26: Blade leading edges | C26: 1 | D26: kit | E26: 60 | F26: =C26*E26 -> 60 | G26: 0 | H26: N | J26: Warp Drive's nickel edge is the $390 alternative
A27: Honda Civic radiator (junkyard) + hoses, clamps, coolant, overflow bottle | B27: Above the hub, in front of the prop | C27: 1 | D27: lot | E27: 140 | F27: =C27*E27 -> 140 | G27: 20 | H27: Y
A28: Radiator cradle rails + straps | B28: On the peak plates | C28: 1 | D28: lot | E28: 35 | F28: =C28*E28 -> 35 | G28: 0.8 | H28: Y
A29: Exhaust: mandrel bends, flex section, muffler, wrap, heat shields | B29: Low starboard; tailpipe over transom below the prop disk | C29: 1 | D29: lot | E29: 280 | F29: =C29*E29 -> 280 | G29: 16 | H29: Y
A30: Throttle cable + return spring | B30: Pedal to throttle body | C30: 1 | D30: lot | E30: 60 | F30: =C30*E30 -> 60 | G30: 1 | H30: N
A31: Rev 6 joint details
A32: A-frame details: slotted leg tops, 1/8 caps, foot gussets, mitred crossbars | B32: 6061 drops; TIG | C32: 1 | D32: lot | E32: 60 | F32: =C32*E32 -> 60 | G32: 0 | H32: Y | J32: Weight included in the A-frame line below
A33: Brace clevises: 1/4 tongues and tab pairs, 3/8 grade 8 bolts + nylocks (4) | B33: Removable braces | C33: 1 | D33: lot | E33: 45 | F33: =C33*E33 -> 45 | G33: 0 | H33: Y
A34: Tie-strut tabs + 5/16 bolts (4) | B34: Adapter to crossbar | C34: 1 | D34: lot | E34: 20 | F34: =C34*E34 -> 20 | G34: 0 | H34: Y
A35: Engine mounts: 6061 cradles (4), steel engine-side brackets (4), DOM sleeves, poly bushings 1.75 OD x 1/2 ID (4), 1/2 grade 8 through-bolts (4) | B35: Engine-side holes to suit the real block | C35: 1 | D35: lot | E35: 160 | F35: =C35*E35 -> 160 | G35: 0 | H35: Y | J35: Measure the G13 mount bosses first
A36: Radiator: lower angle, 2 rubber grommets, 2 x 3/8 top stays with rubber bushings | C36: 1 | D36: lot | E36: 45 | F36: =C36*E36 -> 45 | G36: 0 | H36: Y
A37: Exhaust: flex section, 2 rubber isolators, 2 SS band clamps, 6061 hanger brackets, tailpipe saddle + pad | C37: 1 | D37: lot | E37: 95 | F37: =C37*E37 -> 95 | G37: 0 | H37: Y
A38: Bed-plate bolts 3/8 SS + nylocks + Tef-Gel (20) | B38: All feet and pads | C38: 20 | D38: ea | E38: 1.5 | F38: =C38*E38 -> 30 | G38: 0 | H38: Y
A39: Net weight of the rev 6 drivetrain details (CAD) | B39: Reconciles to the detailed drivetrain model | C39: 1 | D39: lot | E39: 0 | F39: =C39*E39 -> 0 | G39: 14.8 | H39: Y
A41: Total | F41: =SUM(F5:F39) -> 6038 | G41: =SUM(G5:G39) -> 389.4
A42: Weight included in the CAD model | G42: =SUMIF(H5:H39,"Y",G5:G39) -> 385.4
...

Sheet Everything else
A1: DIY Mini-Airboat — Everything else BOM: cage, rudders, steering, seating, controls, flotation, electrical, safety
A2: Costs are 2026 USD estimates. Blue cells are inputs you can change; Est. cost = Qty x Unit cost. Weight is the installed line weight in lb.
A4: Item | B4: Use / spec | C4: Qty | D4: Unit | E4: Unit cost ($) | F4: Est. cost ($) | G4: Weight (lb) | H4: In CAD weight? | I4: Supplier link | J4: Notes
A5: Prop cage
A6: Steel tube 1 in x 0.049 in | B6: Two cage hoops, 72.4 in dia (about 19 ft each) | C6: 40 | D6: ft | E6: 3.5 | F6: =C6*E6 -> 140 | G6: 18.8 | H6: Y
A7: Tube rolling service | B7: Roll two 72.4 in hoops | C7: 1 | D7: job | E7: 150 | F7: =C7*E7 -> 150 | G7: 0 | H7: Y | J7: Muffler or fab shop
A8: Steel tube 1 in x 0.065 in | B8: Cage legs, base rails, rudder rails | C8: 24 | D8: ft | E8: 4 | F8: =C8*E8 -> 96 | G8: 15.5 | H8: Y
A9: EMT conduit 3/4 in and 1/2 in, 10 ft sticks | B9: Longitudinals (8) and face bars (4) | C9: 5 | D9: stick | E9: 10 | F9: =C9*E9 -> 50 | G9: 10.3 | H9: Y | J9: Grind off zinc before welding; ventilate
A10: Hardware cloth 1/2 in, 19 ga galvanized, 36 in x 50 ft | B10: Front, aft and side screens | C10: 1 | D10: roll | E10: 120 | F10: =C10*E10 -> 120 | G10: 17.3 | H10: Y | J10: Keep 4.7 in or more from any moving part
A11: Shaft guard sleeve | B11: Fixed sleeve where the shaft passes the front screen | C11: 1 | D11: ea | E11: 15 | F11: =C11*E11 -> 15 | G11: 0.2 | H11: Y
A12: Welding wire, gas, paint for cage | C12: 1 | D12: lot | E12: 120 | F12: =C12*E12 -> 120 | G12: 0 | H12: N
A13: Rudders and steering
A14: Aluminum honeycomb panel 20 mm, 4 x 8 ft | B14: Two rudders 14 x 44 in | C14: 1 | D14: sheet | E14: 380 | F14: =C14*E14 -> 380 | G14: 11.9 | H14: Y | I14: https://www.chalcoaluminum.com/knowledge/sandwich-panel/#Honeycomb | J14: Price is an estimate; request a quote
A15: Aluminum U-channel 3/4 in, hinge tube 1 in x 0.083 in, horns | B15: Rudder edges and hinges; seal all edges | C15: 1 | D15: lot | E15: 90 | F15: =C15*E15 -> 90 | G15: 5.6 | H15: Y
A16: Hinge brackets and bushings | B16: On the 1 in rudder rails | C16: 4 | D16: ea | E16: 10 | F16: =C16*E16 -> 40 | G16: 0 | H16: N
A17: Tie bar, pushrod, 4 rod ends, lever pivot | B17: Horns to the left-hand steering lever | C17: 1 | D17: lot | E17: 130 | F17: =C17*E17 -> 130 | G17: 4.6 | H17: Y
A18: Seating, controls, fuel, battery
A19: Marine plywood 3/8 in, 4x8 | B19: Floor, transom to x = 121 in, 64 in wide | C19: 5 | D19: sheet | E19: 110 | F19: =C19*E19 -> 550 | G19: 61.7 | H19: Y | J19: Bolt-down panels resting on the stringer tops (aft panel included); 6.5 in cutouts for deck plates
A20: Marine plywood 1/2 in, 4x8 | B20: Straddle bench box and bow shelf | C20: 1 | D20: sheet | E20: 150 | F20: =C20*E20 -> 150 | G20: 33.3 | H20: Y
A21: Bench lid hinge, gasket, latches | B21: Watertight battery compartment | C21: 1 | D21: lot | E21: 70 | F21: =C21*E21 -> 70 | G21: 0 | H21: N
A22: Seat foam + marine vinyl | B22: Bench cushion | C22: 1 | D22: lot | E22: 130 | F22: =C22*E22 -> 130 | G22: 4 | H22: Y
A23: Removable backrests | B23: Driver and passenger | C23: 2 | D23: ea | E23: 55 | F23: =C23*E23 -> 110 | G23: 10 | H23: Y
A24: Passenger grab handles | B24: Both sides of the bench | C24: 2 | D24: ea | E24: 22 | F24: =C24*E24 -> 44 | G24: 3 | H24: Y
A25: Expanded-metal engine guard | B25: Between passenger and engine front | C25: 1 | D25: ea | E25: 60 | F25: =C25*E25 -> 60 | G25: 5 | H25: Y
A26: Footrest ladder | B26: 5 rungs, x = 104.5-123 in | C26: 1 | D26: ea | E26: 45 | F26: =C26*E26 -> 45 | G26: 4 | H26: Y
A27: Throttle pedal, clamp-on | B27: Moves to any ladder rung | C27: 1 | D27: ea | E27: 45 | F27: =C27*E27 -> 45 | G27: 2 | H27: Y
A28: Steering lever + pivot | B28: Port side, left hand | C28: 1 | D28: ea | E28: 70 | F28: =C28*E28 -> 70 | G28: 7 | H28: Y
A29: Padded grab bar | B29: Starboard, right hand at 42 in | C29: 1 | D29: ea | E29: 55 | F29: =C29*E29 -> 55 | G29: 4 | H29: Y
A30: Portable fuel tank 6.6 gal + fuel line and primer bulb | B30: Strapped on the bow shelf | C30: 1 | D30: lot | E30: 120 | F30: =C30*E30 -> 120 | G30: 4.5 | H30: Y | J30: Fuel itself (40 lb full) not counted
A31: Battery, Group 26 + hold-down | B31: Inside the sealed bench | C31: 1 | D31: ea | E31: 150 | F31: =C31*E31 -> 150 | G31: 38 | H31: Y | J31: Lithium option saves about 25 lb
A32: Adjustable trim tab (DIY aluminum) | B32: 18 x 6 in, starboard half of transom | C32: 1 | D32: ea | E32: 60 | F32: =C32*E32 -> 60 | G32: 4 | H32: Y
A33: Flotation, sump, pump
A34: Two-part pour foam, 2 lb/cu ft closed-cell urethane, about 8 cu ft per kit | B34: 24 removable blocks: thin blocks under the floor aft of x = 72 in (5.1 cu ft) and under the bow shelf (4.4 cu ft), poured in molds or in each bay on a release-lined tray | C34: 2 | D34: kit | E34: 115 | F34: =C34*E34 -> 230 | G34: 19 | H34: Y | J34: Urethane only (gasoline resistant); nothing bonded to the aluminum
A35: Coroplast 4 mm 4 x 8 sheets + polyurea or epoxy seal coat | B35: Bottom tray and sealed skin on every block | C35: 1 | D35: lot | E35: 100 | F35: =C35*E35 -> 100 | G35: 3.7 | H35: Y | J35: Sealed skin slows water uptake
A36: HDPE sheet 1/2 in, 12 x 24 in | B36: 54 spacer pads 1.5 x 1.5 in, glued to block bottoms (1/2 in drained channel) | C36: 1 | D36: sheet | E36: 35 | F36: =C36*E36 -> 35 | G36: 2.1 | H36: Y
A37: Two-part pour foam kit + covers and straps | B37: Removable side blocks (6.4 cu ft), molded to fit; they give the swamped boat its stability | C37: 1 | D37: lot | E37: 215 | F37: =C37*E37 -> 215 | G37: 12.8 | H37: Y | J37: Must be strapped in whenever the boat is used
A38: Screw-out deck plates, 6 in | B38: Inspection ports in the floor (8) | C38: 8 | D38: ea | E38: 14 | F38: =C38*E38 -> 112 | G38: 3.6 | H38: Y | J38: Plastic, gasketed
A39: FRP grating panel, 1 in, made into a raised box | B39: Removable grate box over the open sump (pump is taller than the low floor) | C39: 1 | D39: ea | E39: 60 | F39: =C39*E39 -> 60 | G39: 2.5 | H39: Y
A40: Automatic bilge pump about 1,100 gph + float switch | B40: In the open transom sump | C40: 1 | D40: ea | E40: 90 | F40: =C40*E40 -> 90 | G40: 2.5 | H40: Y
A41: Through-hull, discharge hose, clamps | B41: Discharge at 14 in on the transom | C41: 1 | D41: lot | E41: 35 | F41: =C41*E41 -> 35 | G41: 1 | H41: Y
...
