Workbook

Sheet Read me
A1: Straddle Dart build-team ledger: pledges, work done, contributions and ownership
A2: First draft for planning. The rules below are proposals for the team to settle before the first build starts.
A4: How credit works
A5: Every build step is worth the pro labor cost the build guide gives for it (sheet Steps; edit the values there).
A6: A member earns that value either by doing the step or by paying a pro to do it. Fast or slow, the credit is the same.
A7: Several members can share a step: give each one a share (the shares for a step on a boat should add up to 100%).
A8: Credit only counts once another member has checked the work and signed it off (column "Verified by" in the Work log).
A9: If a pro charges more than the step value, the difference can count as a cash contribution (Settings).
A10: Cash, materials, tools and shop space count at their agreed value once another member approves them (Contributions).
A11: A member who withdraws before the build is finished keeps only part of their credit (Settings), which supports the rule
A12: that everyone commits to building every boat, not just up to their own.
A13: Ownership % on the Ownership sheet is each member's counted credit over everyone's. It assumes the team LLC owns all the boats
... A36: This workbook is a planning tool, not a legal agreement. The team's operating agreement, reviewed by a lawyer, governs.

Sheet Settings
A1: Settings
A2: The rules the team agrees before the build. Blue cells are editable.
A4: Setting | B4: Value | C4: Notes
A5: Team / LLC name | B5: Example Straddle Dart Build LLC | C5: As registered
A6: Number of boats in this build | B6: 1 | C6: 1 for the prototype; up to 8
A7: Materials budget per boat ($) | B7: 24452 | C7: From BOM_rev7.xlsx; for the funding target only, not credit
A8: Credit kept by a member who withdraws before the build is finished | B8: 0.5 | C8: Fraction of their credit that still counts
A9: Pro cost above the step value counts as a cash contribution | B9: Yes | C9: Yes or No
A10: Sign-off must be by a different member | B10: Yes | C10: Yes or No

Sheet Members
A1: Members
A2: One row per person. Status: Active, Withdrawn or Finished.
A4: No. | B4: Name | C4: Contact | D4: Joined | E4: Status | F4: Left on | G4: Notes
A5: 1 | B5: Alex (example) | E5: Active
A6: 2 | B6: Bea (example) | E6: Active
A7: 3 | B7: Cruz (example) | E7: Active
A8: 4 | B8: Dana (example) | E8: Active
A9: 5
A10: 6
A11: 7
A12: 8
A13: 9
A14: 10
A15: 11
A16: 12

Sheet Steps
A1: Build steps and their value
A2: From Build_Guide_rev7.xlsx. Value = pro labor cost per boat; edit it if the team agrees a different value.
A4: Step | B4: Section | C4: Step (first line of the guide) | D4: DIY hours | E4: Value per boat ($)
A5: 1 | B5: Hull (riveted aluminum) | C5: Export flat patterns of every skin panel, frame and stringer from the CAD in OnShape; print full-size templates | D5: 6 | E5: 450
A6: 2 | B6: Hull (riveted aluminum) | C6: Build a level strongback (two straight rails on stands) and stand the frames on it as the station molds, braced square and to the CAD spacing; they stay in the hull, so no separate molds are needed | D6: 6 | E6: 420
A7: 3 | B7: Hull (riveted aluminum) | C7: Order 5052-H32 sheet (0.125 in bottom, chine and bow face; 0.063 in sides; 0.125 in transom); have a fab shop shear the blanks and brake the 45 deg chine bends and transom flanges, and brake the two 1/8 in chine-guard strips to 135 deg in the same session | D7: 4 | E7: 650
A8: 4 | B8: Hull (riveted aluminum) | C8: Cut and form stringers (hat or angle sections) to the rocker curve; cut the ten frames from angle (x 12, 24, 36, 48, 60, 72, 84, 96, 111.5 and 120 in; 60 and 84 are copies of 72, 111.5 a copy of 96); notch a 1 x 3/4 in limber in every bay of every frame and a cross-drain slot in every stringer at x 3.5-4.5 | D8: 23 | E8: 1800
A9: 5 | B9: Hull (riveted aluminum) | C9: Cleco frames and stringers together on the jig; check square and diagonals; rivet the framing | D9: 15 | E9: 1180
A10: 6 | B10: Hull (riveted aluminum) | C10: Fit the bottom sheets: flat to x = 120 in, then the conic roll-up tangent into the 15 deg raked bow plate; centerline seam over a doubled center stringer; cleco and trim | D10: 12 | E10: 950
A11: 7 | B11: Hull (riveted aluminum) | C11: Fit chine/side panels, bow face and transom; cleco every lap (1 in minimum); check symmetry and chine angle | D11: 12 | E11: 900
A12: 8 | B12: Hull (riveted aluminum) | C12: Drill all rivet holes to final size (3/16 in) and deburr both sides: double rows at 3/4 in on the bottom centreline seam, the transverse butt seam and the chine laps; double rows at 1 in on the side, transom and bow laps above the waterline | D12: 11.5 | E12: 870
A13: 9 | B13: Hull (riveted aluminum) | C13: Take laps apart, clean, prime faying surfaces and every cut edge with self-etching primer, butter with sealant (Sikaflex 291 or 3M 4200), rivet with closed-end aluminum blind rivets | D13: 20.5 | E13: 1580
A14: 10 | B14: Hull (riveted aluminum) | C14: Install engine beds (doubled aluminum stringers + plates on HDPE), cage mount plates, aluminum rub rail at the sheer | D14: 8 | E14: 600
A15: 11 | B15: Hull (riveted aluminum) | C15: Leak test: hull on stands, fill with 4 in of water, check the outside (before UHMW) for 24 h; mark and fix leakers. Repeat with UHMW on, watching the strip edges | D15: 8 | E15: 600
A16: 12 | B16: Hull (riveted aluminum) | C16: Fit UHMW strips; through-bolt into the stringers with sealant, slotted toward the ends; fit the brake-formed chine guards over the strip edges and the nose cap | D16: 9 | E16: 680
... A62: 58 | B62: Rev 7 additions: driver station, lights, searchlight, power, deck hardware, safety, electrical | C62: Sound check: measure dBA at 50 ft at idle, cruise and full throttle before using noise-limited waters | D62: 2 | E62: 150
C63: Total per boat | D63: =SUM(D5:D62) | E63: =SUM(E5:E62)

Sheet Pledges
A1: Pledges
A2: Who promised which step on which boat. A pledge can be to do the work or to pay a pro for it.
A4: Boat | B4: Step | C4: Step | D4: Member | E4: Share | F4: Target date | G4: Notes | H4: Pledged value ($)
A5: 1 | B5: 1 | C5: =IF(B5="","",IFERROR(INDEX(Steps!$C$5:$C$62,MATCH(B5,Steps!$A$5:$A$62,0)),"")) | D5: Alex (example) | E5: 1 | H5: =IF(OR(B5="",D5=""),0,N(IFERROR(INDEX(Steps!$E$5:$E$62,MATCH(B5,Steps!$A$5:$A$62,0)),""))*E5)
A6: 1 | B6: 2 | C6: =IF(B6="","",IFERROR(INDEX(Steps!$C$5:$C$62,MATCH(B6,Steps!$A$5:$A$62,0)),"")) | D6: Bea (example) | E6: 0.5 | H6: =IF(OR(B6="",D6=""),0,N(IFERROR(INDEX(Steps!$E$5:$E$62,MATCH(B6,Steps!$A$5:$A$62,0)),""))*E6)
A7: 1 | B7: 2 | C7: =IF(B7="","",IFERROR(INDEX(Steps!$C$5:$C$62,MATCH(B7,Steps!$A$5:$A$62,0)),"")) | D7: Cruz (example) | E7: 0.5 | H7: =IF(OR(B7="",D7=""),0,N(IFERROR(INDEX(Steps!$E$5:$E$62,MATCH(B7,Steps!$A$5:$A$62,0)),""))*E7)
A8: 1 | B8: 17 | C8: =IF(B8="","",IFERROR(INDEX(Steps!$C$5:$C$62,MATCH(B8,Steps!$A$5:$A$62,0)),"")) | D8: Dana (example) | E8: 1 | H8: =IF(OR(B8="",D8=""),0,N(IFERROR(INDEX(Steps!$E$5:$E$62,MATCH(B8,Steps!$A$5:$A$62,0)),""))*E8)
A9: 1 | B9: 9 | C9: =IF(B9="","",IFERROR(INDEX(Steps!$C$5:$C$62,MATCH(B9,Steps!$A$5:$A$62,0)),"")) | D9: Cruz (example) | E9: 1 | H9: =IF(OR(B9="",D9=""),0,N(IFERROR(INDEX(Steps!$E$5:$E$62,MATCH(B9,Steps!$A$5:$A$62,0)),""))*E9)
C10: =IF(B10="","",IFERROR(INDEX(Steps!$C$5:$C$62,MATCH(B10,Steps!$A$5:$A$62,0)),"")) | H10: =IF(OR(B10="",D10=""),0,N(IFERROR(INDEX(Steps!$E$5:$E$62,MATCH(B10,Steps!$A$5:$A$62,0)),""))*E10)
C11: =IF(B11="","",IFERROR(INDEX(Steps!$C$5:$C$62,MATCH(B11,Steps!$A$5:$A$62,0)),"")) | H11: =IF(OR(B11="",D11=""),0,N(IFERROR(INDEX(Steps!$E$5:$E$62,MATCH(B11,Steps!$A$5:$A$62,0)),""))*E11)
C12: =IF(B12="","",IFERROR(INDEX(Steps!$C$5:$C$62,MATCH(B12,Steps!$A$5:$A$62,0)),"")) | H12: =IF(OR(B12="",D12=""),0,N(IFERROR(INDEX(Steps!$E$5:$E$62,MATCH(B12,Steps!$A$5:$A$62,0)),""))*E12)
C13: =IF(B13="","",IFERROR(INDEX(Steps!$C$5:$C$62,MATCH(B13,Steps!$A$5:$A$62,0)),"")) | H13: =IF(OR(B13="",D13=""),0,N(IFERROR(INDEX(Steps!$E$5:$E$62,MATCH(B13,Steps!$A$5:$A$62,0)),""))*E13)
C14: =IF(B14="","",IFERROR(INDEX(Steps!$C$5:$C$62,MATCH(B14,Steps!$A$5:$A$62,0)),"")) | H14: =IF(OR(B14="",D14=""),0,N(IFERROR(INDEX(Steps!$E$5:$E$62,MATCH(B14,Steps!$A$5:$A$62,0)),""))*E14)
C15: =IF(B15="","",IFERROR(INDEX(Steps!$C$5:$C$62,MATCH(B15,Steps!$A$5:$A$62,0)),"")) | H15: =IF(OR(B15="",D15=""),0,N(IFERROR(INDEX(Steps!$E$5:$E$62,MATCH(B15,Steps!$A$5:$A$62,0)),""))*E15)
C16: =IF(B16="","",IFERROR(INDEX(Steps!$C$5:$C$62,MATCH(B16,Steps!$A$5:$A$62,0)),"")) | H16: =IF(OR(B16="",D16=""),0,N(IFERROR(INDEX(Steps!$E$5:$E$62,MATCH(B16,Steps!$A$5:$A$62,0)),""))*E16)
C17: =IF(B17="","",IFERROR(INDEX(Steps!$C$5:$C$62,MATCH(B17,Steps!$A$5:$A$62,0)),"")) | H17: =IF(OR(B17="",D17=""),0,N(IFERROR(INDEX(Steps!$E$5:$E$62,MATCH(B17,Steps!$A$5:$A$62,0)),""))*E17)
C18: =IF(B18="","",IFERROR(INDEX(Steps!$C$5:$C$62,MATCH(B18,Steps!$A$5:$A$62,0)),"")) | H18: =IF(OR(B18="",D18=""),0,N(IFERROR(INDEX(Steps!$E$5:$E$62,MATCH(B18,Steps!$A$5:$A$62,0)),""))*E18)
C19: =IF(B19="","",IFERROR(INDEX(Steps!$C$5:$C$62,MATCH(B19,Steps!$A$5:$A$62,0)),"")) | H19: =IF(OR(B19="",D19=""),0,N(IFERROR(INDEX(Steps!$E$5:$E$62,MATCH(B19,Steps!$A$5:$A$62,0)),""))*E19)
C20: =IF(B20="","",IFERROR(INDEX(Steps!$C$5:$C$62,MATCH(B20,Steps!$A$5:$A$62,0)),"")) | H20: =IF(OR(B20="",D20=""),0,N(IFERROR(INDEX(Steps!$E$5:$E$62,MATCH(B20,Steps!$A$5:$A$62,0)),""))*E20)
C21: =IF(B21="","",IFERROR(INDEX(Steps!$C$5:$C$62,MATCH(B21,Steps!$A$5:$A$62,0)),"")) | H21: =IF(OR(B21="",D21=""),0,N(IFERROR(INDEX(Steps!$E$5:$E$62,MATCH(B21,Steps!$A$5:$A$62,0)),""))*E21)
... C504: =IF(B504="","",IFERROR(INDEX(Steps!$C$5:$C$62,MATCH(B504,Steps!$A$5:$A$62,0)),"")) | H504: =IF(OR(B504="",D504=""),0,N(IFERROR(INDEX(Steps!$E$5:$E$62,MATCH(B504,Steps!$A$5:$A$62,0)),""))*E504)

Sheet Work log
A1: Work log
A2: One row per member per step finished. Credit counts once a different member signs it off.
A4: Date done | B4: Boat | C4: Step | D4: Step | E4: Member | F4: Share | G4: How | H4: Pro invoice ($) | I4: Verified by | J4: Verified on | K4: Step value ($) | L4: Credit ($) | M4: Pro overrun as cash ($) | N4: Check
A5: 46396 | B5: 1 | C5: 1 | D5: =IF(C5="","",IFERROR(INDEX(Steps!$C$5:$C$62,MATCH(C5,Steps!$A$5:$A$62,0)),"")) | E5: Alex (example) | F5: 1 | G5: Did it myself | I5: Bea (example) | K5: =IF(C5="","",N(IFERROR(INDEX(Steps!$E$5:$E$62,MATCH(C5,Steps!$A$5:$A$62,0)),""))) | L5: =IF(AND(C5<>"",E5<>"",I5<>"",OR(Settings!$B$10="No",I5<>E5)),K5*F5,0) | M5: =IF(AND(AND(C5<>"",E5<>"",I5<>"",OR(Settings!$B$10="No",I5<>E5)),G5="Paid a pro",Settings!$B$9="Yes"),MAX(0,H5-K5*F5),0) | N5: =IF(C5="","",IF(B5="","Enter the boat number",IF(B5>Settings!$B$6,"Boat number above the boat count",IF(SUMIFS($F$5:$F$1004,$B$5:$B$1004,B5,$C$5:$C$1004,C5)>1.0001,"Shares for this step add up to over 100%",IF(I5="","Waiting for sign-off",IF(AND(Settings!$B$10="Yes",I5=E5),"Needs a different member to sign off","OK"))))))
A6: 46403 | B6: 1 | C6: 2 | D6: =IF(C6="","",IFERROR(INDEX(Steps!$C$5:$C$62,MATCH(C6,Steps!$A$5:$A$62,0)),"")) | E6: Bea (example) | F6: 0.5 | G6: Did it myself | I6: Alex (example) | K6: =IF(C6="","",N(IFERROR(INDEX(Steps!$E$5:$E$62,MATCH(C6,Steps!$A$5:$A$62,0)),""))) | L6: =IF(AND(C6<>"",E6<>"",I6<>"",OR(Settings!$B$10="No",I6<>E6)),K6*F6,0) | M6: =IF(AND(AND(C6<>"",E6<>"",I6<>"",OR(Settings!$B$10="No",I6<>E6)),G6="Paid a pro",Settings!$B$9="Yes"),MAX(0,H6-K6*F6),0) | N6: =IF(C6="","",IF(B6="","Enter the boat number",IF(B6>Settings!$B$6,"Boat number above the boat count",IF(SUMIFS($F$5:$F$1004,$B$5:$B$1004,B6,$C$5:$C$1004,C6)>1.0001,"Shares for this step add up to over 100%",IF(I6="","Waiting for sign-off",IF(AND(Settings!$B$10="Yes",I6=E6),"Needs a different member to sign off","OK"))))))
A7: 46403 | B7: 1 | C7: 2 | D7: =IF(C7="","",IFERROR(INDEX(Steps!$C$5:$C$62,MATCH(C7,Steps!$A$5:$A$62,0)),"")) | E7: Cruz (example) | F7: 0.5 | G7: Did it myself | I7: Cruz (example) | K7: =IF(C7="","",N(IFERROR(INDEX(Steps!$E$5:$E$62,MATCH(C7,Steps!$A$5:$A$62,0)),""))) | L7: =IF(AND(C7<>"",E7<>"",I7<>"",OR(Settings!$B$10="No",I7<>E7)),K7*F7,0) | M7: =IF(AND(AND(C7<>"",E7<>"",I7<>"",OR(Settings!$B$10="No",I7<>E7)),G7="Paid a pro",Settings!$B$9="Yes"),MAX(0,H7-K7*F7),0) | N7: =IF(C7="","",IF(B7="","Enter the boat number",IF(B7>Settings!$B$6,"Boat number above the boat count",IF(SUMIFS($F$5:$F$1004,$B$5:$B$1004,B7,$C$5:$C$1004,C7)>1.0001,"Shares for this step add up to over 100%",IF(I7="","Waiting for sign-off",IF(AND(Settings!$B$10="Yes",I7=E7),"Needs a different member to sign off","OK"))))))
A8: 46438 | B8: 1 | C8: 17 | D8: =IF(C8="","",IFERROR(INDEX(Steps!$C$5:$C$62,MATCH(C8,Steps!$A$5:$A$62,0)),"")) | E8: Dana (example) | F8: 1 | G8: Paid a pro | H8: 2900 | I8: Alex (example) | K8: =IF(C8="","",N(IFERROR(INDEX(Steps!$E$5:$E$62,MATCH(C8,Steps!$A$5:$A$62,0)),""))) | L8: =IF(AND(C8<>"",E8<>"",I8<>"",OR(Settings!$B$10="No",I8<>E8)),K8*F8,0) | M8: =IF(AND(AND(C8<>"",E8<>"",I8<>"",OR(Settings!$B$10="No",I8<>E8)),G8="Paid a pro",Settings!$B$9="Yes"),MAX(0,H8-K8*F8),0) | N8: =IF(C8="","",IF(B8="","Enter the boat number",IF(B8>Settings!$B$6,"Boat number above the boat count",IF(SUMIFS($F$5:$F$1004,$B$5:$B$1004,B8,$C$5:$C$1004,C8)>1.0001,"Shares for this step add up to over 100%",IF(I8="","Waiting for sign-off",IF(AND(Settings!$B$10="Yes",I8=E8),"Needs a different member to sign off","OK"))))))
D9: =IF(C9="","",IFERROR(INDEX(Steps!$C$5:$C$62,MATCH(C9,Steps!$A$5:$A$62,0)),"")) | K9: =IF(C9="","",N(IFERROR(INDEX(Steps!$E$5:$E$62,MATCH(C9,Steps!$A$5:$A$62,0)),""))) | L9: =IF(AND(C9<>"",E9<>"",I9<>"",OR(Settings!$B$10="No",I9<>E9)),K9*F9,0) | M9: =IF(AND(AND(C9<>"",E9<>"",I9<>"",OR(Settings!$B$10="No",I9<>E9)),G9="Paid a pro",Settings!$B$9="Yes"),MAX(0,H9-K9*F9),0) | N9: =IF(C9="","",IF(B9="","Enter the boat number",IF(B9>Settings!$B$6,"Boat number above the boat count",IF(SUMIFS($F$5:$F$1004,$B$5:$B$1004,B9,$C$5:$C$1004,C9)>1.0001,"Shares for this step add up to over 100%",IF(I9="","Waiting for sign-off",IF(AND(Settings!$B$10="Yes",I9=E9),"Needs a different member to sign off","OK"))))))
D10: =IF(C10="","",IFERROR(INDEX(Steps!$C$5:$C$62,MATCH(C10,Steps!$A$5:$A$62,0)),"")) | K10: =IF(C10="","",N(IFERROR(INDEX(Steps!$E$5:$E$62,MATCH(C10,Steps!$A$5:$A$62,0)),""))) | L10: =IF(AND(C10<>"",E10<>"",I10<>"",OR(Settings!$B$10="No",I10<>E10)),K10*F10,0) | M10: =IF(AND(AND(C10<>"",E10<>"",I10<>"",OR(Settings!$B$10="No",I10<>E10)),G10="Paid a pro",Settings!$B$9="Yes"),MAX(0,H10-K10*F10),0) | N10: =IF(C10="","",IF(B10="","Enter the boat number",IF(B10>Settings!$B$6,"Boat number above the boat count",IF(SUMIFS($F$5:$F$1004,$B$5:$B$1004,B10,$C$5:$C$1004,C10)>1.0001,"Shares for this step add up to over 100%",IF(I10="","Waiting for sign-off",IF(AND(Settings!$B$10="Yes",I10=E10),"Needs a different member to sign off","OK"))))))
D11: =IF(C11="","",IFERROR(INDEX(Steps!$C$5:$C$62,MATCH(C11,Steps!$A$5:$A$62,0)),"")) | K11: =IF(C11="","",N(IFERROR(INDEX(Steps!$E$5:$E$62,MATCH(C11,Steps!$A$5:$A$62,0)),""))) | L11: =IF(AND(C11<>"",E11<>"",I11<>"",OR(Settings!$B$10="No",I11<>E11)),K11*F11,0) | M11: =IF(AND(AND(C11<>"",E11<>"",I11<>"",OR(Settings!$B$10="No",I11<>E11)),G11="Paid a pro",Settings!$B$9="Yes"),MAX(0,H11-K11*F11),0) | N11: =IF(C11="","",IF(B11="","Enter the boat number",IF(B11>Settings!$B$6,"Boat number above the boat count",IF(SUMIFS($F$5:$F$1004,$B$5:$B$1004,B11,$C$5:$C$1004,C11)>1.0001,"Shares for this step add up to over 100%",IF(I11="","Waiting for sign-off",IF(AND(Settings!$B$10="Yes",I11=E11),"Needs a different member to sign off","OK"))))))
D12: =IF(C12="","",IFERROR(INDEX(Steps!$C$5:$C$62,MATCH(C12,Steps!$A$5:$A$62,0)),"")) | K12: =IF(C12="","",N(IFERROR(INDEX(Steps!$E$5:$E$62,MATCH(C12,Steps!$A$5:$A$62,0)),""))) | L12: =IF(AND(C12<>"",E12<>"",I12<>"",OR(Settings!$B$10="No",I12<>E12)),K12*F12,0) | M12: =IF(AND(AND(C12<>"",E12<>"",I12<>"",OR(Settings!$B$10="No",I12<>E12)),G12="Paid a pro",Settings!$B$9="Yes"),MAX(0,H12-K12*F12),0) | N12: =IF(C12="","",IF(B12="","Enter the boat number",IF(B12>Settings!$B$6,"Boat number above the boat count",IF(SUMIFS($F$5:$F$1004,$B$5:$B$1004,B12,$C$5:$C$1004,C12)>1.0001,"Shares for this step add up to over 100%",IF(I12="","Waiting for sign-off",IF(AND(Settings!$B$10="Yes",I12=E12),"Needs a different member to sign off","OK"))))))
D13: =IF(C13="","",IFERROR(INDEX(Steps!$C$5:$C$62,MATCH(C13,Steps!$A$5:$A$62,0)),"")) | K13: =IF(C13="","",N(IFERROR(INDEX(Steps!$E$5:$E$62,MATCH(C13,Steps!$A$5:$A$62,0)),""))) | L13: =IF(AND(C13<>"",E13<>"",I13<>"",OR(Settings!$B$10="No",I13<>E13)),K13*F13,0) | M13: =IF(AND(AND(C13<>"",E13<>"",I13<>"",OR(Settings!$B$10="No",I13<>E13)),G13="Paid a pro",Settings!$B$9="Yes"),MAX(0,H13-K13*F13),0) | N13: =IF(C13="","",IF(B13="","Enter the boat number",IF(B13>Settings!$B$6,"Boat number above the boat count",IF(SUMIFS($F$5:$F$1004,$B$5:$B$1004,B13,$C$5:$C$1004,C13)>1.0001,"Shares for this step add up to over 100%",IF(I13="","Waiting for sign-off",IF(AND(Settings!$B$10="Yes",I13=E13),"Needs a different member to sign off","OK"))))))
D14: =IF(C14="","",IFERROR(INDEX(Steps!$C$5:$C$62,MATCH(C14,Steps!$A$5:$A$62,0)),"")) | K14: =IF(C14="","",N(IFERROR(INDEX(Steps!$E$5:$E$62,MATCH(C14,Steps!$A$5:$A$62,0)),""))) | L14: =IF(AND(C14<>"",E14<>"",I14<>"",OR(Settings!$B$10="No",I14<>E14)),K14*F14,0) | M14: =IF(AND(AND(C14<>"",E14<>"",I14<>"",OR(Settings!$B$10="No",I14<>E14)),G14="Paid a pro",Settings!$B$9="Yes"),MAX(0,H14-K14*F14),0) | N14: =IF(C14="","",IF(B14="","Enter the boat number",IF(B14>Settings!$B$6,"Boat number above the boat count",IF(SUMIFS($F$5:$F$1004,$B$5:$B$1004,B14,$C$5:$C$1004,C14)>1.0001,"Shares for this step add up to over 100%",IF(I14="","Waiting for sign-off",IF(AND(Settings!$B$10="Yes",I14=E14),"Needs a different member to sign off","OK"))))))
D15: =IF(C15="","",IFERROR(INDEX(Steps!$C$5:$C$62,MATCH(C15,Steps!$A$5:$A$62,0)),"")) | K15: =IF(C15="","",N(IFERROR(INDEX(Steps!$E$5:$E$62,MATCH(C15,Steps!$A$5:$A$62,0)),""))) | L15: =IF(AND(C15<>"",E15<>"",I15<>"",OR(Settings!$B$10="No",I15<>E15)),K15*F15,0) | M15: =IF(AND(AND(C15<>"",E15<>"",I15<>"",OR(Settings!$B$10="No",I15<>E15)),G15="Paid a pro",Settings!$B$9="Yes"),MAX(0,H15-K15*F15),0) | N15: =IF(C15="","",IF(B15="","Enter the boat number",IF(B15>Settings!$B$6,"Boat number above the boat count",IF(SUMIFS($F$5:$F$1004,$B$5:$B$1004,B15,$C$5:$C$1004,C15)>1.0001,"Shares for this step add up to over 100%",IF(I15="","Waiting for sign-off",IF(AND(Settings!$B$10="Yes",I15=E15),"Needs a different member to sign off","OK"))))))
D16: =IF(C16="","",IFERROR(INDEX(Steps!$C$5:$C$62,MATCH(C16,Steps!$A$5:$A$62,0)),"")) | K16: =IF(C16="","",N(IFERROR(INDEX(Steps!$E$5:$E$62,MATCH(C16,Steps!$A$5:$A$62,0)),""))) | L16: =IF(AND(C16<>"",E16<>"",I16<>"",OR(Settings!$B$10="No",I16<>E16)),K16*F16,0) | M16: =IF(AND(AND(C16<>"",E16<>"",I16<>"",OR(Settings!$B$10="No",I16<>E16)),G16="Paid a pro",Settings!$B$9="Yes"),MAX(0,H16-K16*F16),0) | N16: =IF(C16="","",IF(B16="","Enter the boat number",IF(B16>Settings!$B$6,"Boat number above the boat count",IF(SUMIFS($F$5:$F$1004,$B$5:$B$1004,B16,$C$5:$C$1004,C16)>1.0001,"Shares for this step add up to over 100%",IF(I16="","Waiting for sign-off",IF(AND(Settings!$B$10="Yes",I16=E16),"Needs a different member to sign off","OK"))))))
D17: =IF(C17="","",IFERROR(INDEX(Steps!$C$5:$C$62,MATCH(C17,Steps!$A$5:$A$62,0)),"")) | K17: =IF(C17="","",N(IFERROR(INDEX(Steps!$E$5:$E$62,MATCH(C17,Steps!$A$5:$A$62,0)),""))) | L17: =IF(AND(C17<>"",E17<>"",I17<>"",OR(Settings!$B$10="No",I17<>E17)),K17*F17,0) | M17: =IF(AND(AND(C17<>"",E17<>"",I17<>"",OR(Settings!$B$10="No",I17<>E17)),G17="Paid a pro",Settings!$B$9="Yes"),MAX(0,H17-K17*F17),0) | N17: =IF(C17="","",IF(B17="","Enter the boat number",IF(B17>Settings!$B$6,"Boat number above the boat count",IF(SUMIFS($F$5:$F$1004,$B$5:$B$1004,B17,$C$5:$C$1004,C17)>1.0001,"Shares for this step add up to over 100%",IF(I17="","Waiting for sign-off",IF(AND(Settings!$B$10="Yes",I17=E17),"Needs a different member to sign off","OK"))))))
D18: =IF(C18="","",IFERROR(INDEX(Steps!$C$5:$C$62,MATCH(C18,Steps!$A$5:$A$62,0)),"")) | K18: =IF(C18="","",N(IFERROR(INDEX(Steps!$E$5:$E$62,MATCH(C18,Steps!$A$5:$A$62,0)),""))) | L18: =IF(AND(C18<>"",E18<>"",I18<>"",OR(Settings!$B$10="No",I18<>E18)),K18*F18,0) | M18: =IF(AND(AND(C18<>"",E18<>"",I18<>"",OR(Settings!$B$10="No",I18<>E18)),G18="Paid a pro",Settings!$B$9="Yes"),MAX(0,H18-K18*F18),0) | N18: =IF(C18="","",IF(B18="","Enter the boat number",IF(B18>Settings!$B$6,"Boat number above the boat count",IF(SUMIFS($F$5:$F$1004,$B$5:$B$1004,B18,$C$5:$C$1004,C18)>1.0001,"Shares for this step add up to over 100%",IF(I18="","Waiting for sign-off",IF(AND(Settings!$B$10="Yes",I18=E18),"Needs a different member to sign off","OK"))))))
D19: =IF(C19="","",IFERROR(INDEX(Steps!$C$5:$C$62,MATCH(C19,Steps!$A$5:$A$62,0)),"")) | K19: =IF(C19="","",N(IFERROR(INDEX(Steps!$E$5:$E$62,MATCH(C19,Steps!$A$5:$A$62,0)),""))) | L19: =IF(AND(C19<>"",E19<>"",I19<>"",OR(Settings!$B$10="No",I19<>E19)),K19*F19,0) | M19: =IF(AND(AND(C19<>"",E19<>"",I19<>"",OR(Settings!$B$10="No",I19<>E19)),G19="Paid a pro",Settings!$B$9="Yes"),MAX(0,H19-K19*F19),0) | N19: =IF(C19="","",IF(B19="","Enter the boat number",IF(B19>Settings!$B$6,"Boat number above the boat count",IF(SUMIFS($F$5:$F$1004,$B$5:$B$1004,B19,$C$5:$C$1004,C19)>1.0001,"Shares for this step add up to over 100%",IF(I19="","Waiting for sign-off",IF(AND(Settings!$B$10="Yes",I19=E19),"Needs a different member to sign off","OK"))))))
D20: =IF(C20="","",IFERROR(INDEX(Steps!$C$5:$C$62,MATCH(C20,Steps!$A$5:$A$62,0)),"")) | K20: =IF(C20="","",N(IFERROR(INDEX(Steps!$E$5:$E$62,MATCH(C20,Steps!$A$5:$A$62,0)),""))) | L20: =IF(AND(C20<>"",E20<>"",I20<>"",OR(Settings!$B$10="No",I20<>E20)),K20*F20,0) | M20: =IF(AND(AND(C20<>"",E20<>"",I20<>"",OR(Settings!$B$10="No",I20<>E20)),G20="Paid a pro",Settings!$B$9="Yes"),MAX(0,H20-K20*F20),0) | N20: =IF(C20="","",IF(B20="","Enter the boat number",IF(B20>Settings!$B$6,"Boat number above the boat count",IF(SUMIFS($F$5:$F$1004,$B$5:$B$1004,B20,$C$5:$C$1004,C20)>1.0001,"Shares for this step add up to over 100%",IF(I20="","Waiting for sign-off",IF(AND(Settings!$B$10="Yes",I20=E20),"Needs a different member to sign off","OK"))))))
... D1004: =IF(C1004="","",IFERROR(INDEX(Steps!$C$5:$C$62,MATCH(C1004,Steps!$A$5:$A$62,0)),"")) | K1004: =IF(C1004="","",N(IFERROR(INDEX(Steps!$E$5:$E$62,MATCH(C1004,Steps!$A$5:$A$62,0)),""))) | L1004: =IF(AND(C1004<>"",E1004<>"",I1004<>"",OR(Settings!$B$10="No",I1004<>E1004)),K1004*F1004,0) | M1004: =IF(AND(AND(C1004<>"",E1004<>"",I1004<>"",OR(Settings!$B$10="No",I1004<>E1004)),G1004="Paid a pro",Settings!$B$9="Yes"),MAX(0,H1004-K1004*F1004),0) | N1004: =IF(C1004="","",IF(B1004="","Enter the boat number",IF(B1004>Settings!$B$6,"Boat number above the boat count",IF(SUMIFS($F$5:$F$1004,$B$5:$B$1004,B1004,$C$5:$C$1004,C1004)>1.0001,"Shares for this step add up to over 100%",IF(I1004="","Waiting for sign-off",IF(AND(Settings!$B$10="Yes",I1004=E1004),"Needs a different member to sign off","OK"))))))

Sheet Contributions
A1: Contributions
A2: Cash, materials, tools and shop space at their agreed value. Counts once a different member approves it.
A4: Date | B4: Member | C4: Type | D4: Description | E4: Agreed value ($) | F4: Approved by | G4: Credit ($)
A5: 46392 | B5: Alex (example) | C5: Cash | D5: Prototype fund | E5: 1000 | F5: Bea (example) | G5: =IF(AND(B5<>"",F5<>"",OR(Settings!$B$10="No",F5<>B5)),N(E5),0)
A6: 46396 | B6: Cruz (example) | C6: Tools or equipment | D6: Rivet gun and cleco set, kept by the team | E6: 300 | F6: Alex (example) | G6: =IF(AND(B6<>"",F6<>"",OR(Settings!$B$10="No",F6<>B6)),N(E6),0)
G7: =IF(AND(B7<>"",F7<>"",OR(Settings!$B$10="No",F7<>B7)),N(E7),0)
G8: =IF(AND(B8<>"",F8<>"",OR(Settings!$B$10="No",F8<>B8)),N(E8),0)
G9: =IF(AND(B9<>"",F9<>"",OR(Settings!$B$10="No",F9<>B9)),N(E9),0)
G10: =IF(AND(B10<>"",F10<>"",OR(Settings!$B$10="No",F10<>B10)),N(E10),0)
G11: =IF(AND(B11<>"",F11<>"",OR(Settings!$B$10="No",F11<>B11)),N(E11),0)
G12: =IF(AND(B12<>"",F12<>"",OR(Settings!$B$10="No",F12<>B12)),N(E12),0)
G13: =IF(AND(B13<>"",F13<>"",OR(Settings!$B$10="No",F13<>B13)),N(E13),0)
G14: =IF(AND(B14<>"",F14<>"",OR(Settings!$B$10="No",F14<>B14)),N(E14),0)
G15: =IF(AND(B15<>"",F15<>"",OR(Settings!$B$10="No",F15<>B15)),N(E15),0)
G16: =IF(AND(B16<>"",F16<>"",OR(Settings!$B$10="No",F16<>B16)),N(E16),0)
G17: =IF(AND(B17<>"",F17<>"",OR(Settings!$B$10="No",F17<>B17)),N(E17),0)
G18: =IF(AND(B18<>"",F18<>"",OR(Settings!$B$10="No",F18<>B18)),N(E18),0)
... G304: =IF(AND(B304<>"",F304<>"",OR(Settings!$B$10="No",F304<>B304)),N(E304),0)

Sheet Progress
A1: Progress by step and boat
A2: Share of each step done and signed off, and (right) share pledged. Columns past the boat count stay blank.
A4: Step | B4: Step | C4: Value ($) | D4: Boat 1 done | E4: Boat 2 done | F4: Boat 3 done | G4: Boat 4 done | H4: Boat 5 done | I4: Boat 6 done | J4: Boat 7 done | K4: Boat 8 done | L4: Boat 1 pledged | M4: Boat 2 pledged | N4: Boat 3 pledged | O4: Boat 4 pledged | P4: Boat 5 pledged | Q4: Boat 6 pledged | R4: Boat 7 pledged | S4: Boat 8 pledged
A5: =Steps!A5 | B5: =Steps!C5 | C5: =Steps!E5 | D5: =IF(1>Settings!$B$6,"",SUMIFS('Work log'!$F$5:$F$1004,'Work log'!$B$5:$B$1004,1,'Work log'!$C$5:$C$1004,A5,'Work log'!$L$5:$L$1004,">0")) | E5: =IF(2>Settings!$B$6,"",SUMIFS('Work log'!$F$5:$F$1004,'Work log'!$B$5:$B$1004,2,'Work log'!$C$5:$C$1004,A5,'Work log'!$L$5:$L$1004,">0")) | F5: =IF(3>Settings!$B$6,"",SUMIFS('Work log'!$F$5:$F$1004,'Work log'!$B$5:$B$1004,3,'Work log'!$C$5:$C$1004,A5,'Work log'!$L$5:$L$1004,">0")) | G5: =IF(4>Settings!$B$6,"",SUMIFS('Work log'!$F$5:$F$1004,'Work log'!$B$5:$B$1004,4,'Work log'!$C$5:$C$1004,A5,'Work log'!$L$5:$L$1004,">0")) | H5: =IF(5>Settings!$B$6,"",SUMIFS('Work log'!$F$5:$F$1004,'Work log'!$B$5:$B$1004,5,'Work log'!$C$5:$C$1004,A5,'Work log'!$L$5:$L$1004,">0")) | I5: =IF(6>Settings!$B$6,"",SUMIFS('Work log'!$F$5:$F$1004,'Work log'!$B$5:$B$1004,6,'Work log'!$C$5:$C$1004,A5,'Work log'!$L$5:$L$1004,">0")) | J5: =IF(7>Settings!$B$6,"",SUMIFS('Work log'!$F$5:$F$1004,'Work log'!$B$5:$B$1004,7,'Work log'!$C$5:$C$1004,A5,'Work log'!$L$5:$L$1004,">0")) | K5: =IF(8>Settings!$B$6,"",SUMIFS('Work log'!$F$5:$F$1004,'Work log'!$B$5:$B$1004,8,'Work log'!$C$5:$C$1004,A5,'Work log'!$L$5:$L$1004,">0")) | L5: =IF(1>Settings!$B$6,"",SUMIFS(Pledges!$E$5:$E$504,Pledges!$A$5:$A$504,1,Pledges!$B$5:$B$504,A5)) | M5: =IF(2>Settings!$B$6,"",SUMIFS(Pledges!$E$5:$E$504,Pledges!$A$5:$A$504,2,Pledges!$B$5:$B$504,A5)) | N5: =IF(3>Settings!$B$6,"",SUMIFS(Pledges!$E$5:$E$504,Pledges!$A$5:$A$504,3,Pledges!$B$5:$B$504,A5)) | O5: =IF(4>Settings!$B$6,"",SUMIFS(Pledges!$E$5:$E$504,Pledges!$A$5:$A$504,4,Pledges!$B$5:$B$504,A5)) | P5: =IF(5>Settings!$B$6,"",SUMIFS(Pledges!$E$5:$E$504,Pledges!$A$5:$A$504,5,Pledges!$B$5:$B$504,A5)) | Q5: =IF(6>Settings!$B$6,"",SUMIFS(Pledges!$E$5:$E$504,Pledges!$A$5:$A$504,6,Pledges!$B$5:$B$504,A5)) | R5: =IF(7>Settings!$B$6,"",SUMIFS(Pledges!$E$5:$E$504,Pledges!$A$5:$A$504,7,Pledges!$B$5:$B$504,A5)) | S5: =IF(8>Settings!$B$6,"",SUMIFS(Pledges!$E$5:$E$504,Pledges!$A$5:$A$504,8,Pledges!$B$5:$B$504,A5))
A6: =Steps!A6 | B6: =Steps!C6 | C6: =Steps!E6 | D6: =IF(1>Settings!$B$6,"",SUMIFS('Work log'!$F$5:$F$1004,'Work log'!$B$5:$B$1004,1,'Work log'!$C$5:$C$1004,A6,'Work log'!$L$5:$L$1004,">0")) | E6: =IF(2>Settings!$B$6,"",SUMIFS('Work log'!$F$5:$F$1004,'Work log'!$B$5:$B$1004,2,'Work log'!$C$5:$C$1004,A6,'Work log'!$L$5:$L$1004,">0")) | F6: =IF(3>Settings!$B$6,"",SUMIFS('Work log'!$F$5:$F$1004,'Work log'!$B$5:$B$1004,3,'Work log'!$C$5:$C$1004,A6,'Work log'!$L$5:$L$1004,">0")) | G6: =IF(4>Settings!$B$6,"",SUMIFS('Work log'!$F$5:$F$1004,'Work log'!$B$5:$B$1004,4,'Work log'!$C$5:$C$1004,A6,'Work log'!$L$5:$L$1004,">0")) | H6: =IF(5>Settings!$B$6,"",SUMIFS('Work log'!$F$5:$F$1004,'Work log'!$B$5:$B$1004,5,'Work log'!$C$5:$C$1004,A6,'Work log'!$L$5:$L$1004,">0")) | I6: =IF(6>Settings!$B$6,"",SUMIFS('Work log'!$F$5:$F$1004,'Work log'!$B$5:$B$1004,6,'Work log'!$C$5:$C$1004,A6,'Work log'!$L$5:$L$1004,">0")) | J6: =IF(7>Settings!$B$6,"",SUMIFS('Work log'!$F$5:$F$1004,'Work log'!$B$5:$B$1004,7,'Work log'!$C$5:$C$1004,A6,'Work log'!$L$5:$L$1004,">0")) | K6: =IF(8>Settings!$B$6,"",SUMIFS('Work log'!$F$5:$F$1004,'Work log'!$B$5:$B$1004,8,'Work log'!$C$5:$C$1004,A6,'Work log'!$L$5:$L$1004,">0")) | L6: =IF(1>Settings!$B$6,"",SUMIFS(Pledges!$E$5:$E$504,Pledges!$A$5:$A$504,1,Pledges!$B$5:$B$504,A6)) | M6: =IF(2>Settings!$B$6,"",SUMIFS(Pledges!$E$5:$E$504,Pledges!$A$5:$A$504,2,Pledges!$B$5:$B$504,A6)) | N6: =IF(3>Settings!$B$6,"",SUMIFS(Pledges!$E$5:$E$504,Pledges!$A$5:$A$504,3,Pledges!$B$5:$B$504,A6)) | O6: =IF(4>Settings!$B$6,"",SUMIFS(Pledges!$E$5:$E$504,Pledges!$A$5:$A$504,4,Pledges!$B$5:$B$504,A6)) | P6: =IF(5>Settings!$B$6,"",SUMIFS(Pledges!$E$5:$E$504,Pledges!$A$5:$A$504,5,Pledges!$B$5:$B$504,A6)) | Q6: =IF(6>Settings!$B$6,"",SUMIFS(Pledges!$E$5:$E$504,Pledges!$A$5:$A$504,6,Pledges!$B$5:$B$504,A6)) | R6: =IF(7>Settings!$B$6,"",SUMIFS(Pledges!$E$5:$E$504,Pledges!$A$5:$A$504,7,Pledges!$B$5:$B$504,A6)) | S6: =IF(8>Settings!$B$6,"",SUMIFS(Pledges!$E$5:$E$504,Pledges!$A$5:$A$504,8,Pledges!$B$5:$B$504,A6))
A7: =Steps!A7 | B7: =Steps!C7 | C7: =Steps!E7 | D7: =IF(1>Settings!$B$6,"",SUMIFS('Work log'!$F$5:$F$1004,'Work log'!$B$5:$B$1004,1,'Work log'!$C$5:$C$1004,A7,'Work log'!$L$5:$L$1004,">0")) | E7: =IF(2>Settings!$B$6,"",SUMIFS('Work log'!$F$5:$F$1004,'Work log'!$B$5:$B$1004,2,'Work log'!$C$5:$C$1004,A7,'Work log'!$L$5:$L$1004,">0")) | F7: =IF(3>Settings!$B$6,"",SUMIFS('Work log'!$F$5:$F$1004,'Work log'!$B$5:$B$1004,3,'Work log'!$C$5:$C$1004,A7,'Work log'!$L$5:$L$1004,">0")) | G7: =IF(4>Settings!$B$6,"",SUMIFS('Work log'!$F$5:$F$1004,'Work log'!$B$5:$B$1004,4,'Work log'!$C$5:$C$1004,A7,'Work log'!$L$5:$L$1004,">0")) | H7: =IF(5>Settings!$B$6,"",SUMIFS('Work log'!$F$5:$F$1004,'Work log'!$B$5:$B$1004,5,'Work log'!$C$5:$C$1004,A7,'Work log'!$L$5:$L$1004,">0")) | I7: =IF(6>Settings!$B$6,"",SUMIFS('Work log'!$F$5:$F$1004,'Work log'!$B$5:$B$1004,6,'Work log'!$C$5:$C$1004,A7,'Work log'!$L$5:$L$1004,">0")) | J7: =IF(7>Settings!$B$6,"",SUMIFS('Work log'!$F$5:$F$1004,'Work log'!$B$5:$B$1004,7,'Work log'!$C$5:$C$1004,A7,'Work log'!$L$5:$L$1004,">0")) | K7: =IF(8>Settings!$B$6,"",SUMIFS('Work log'!$F$5:$F$1004,'Work log'!$B$5:$B$1004,8,'Work log'!$C$5:$C$1004,A7,'Work log'!$L$5:$L$1004,">0")) | L7: =IF(1>Settings!$B$6,"",SUMIFS(Pledges!$E$5:$E$504,Pledges!$A$5:$A$504,1,Pledges!$B$5:$B$504,A7)) | M7: =IF(2>Settings!$B$6,"",SUMIFS(Pledges!$E$5:$E$504,Pledges!$A$5:$A$504,2,Pledges!$B$5:$B$504,A7)) | N7: =IF(3>Settings!$B$6,"",SUMIFS(Pledges!$E$5:$E$504,Pledges!$A$5:$A$504,3,Pledges!$B$5:$B$504,A7)) | O7: =IF(4>Settings!$B$6,"",SUMIFS(Pledges!$E$5:$E$504,Pledges!$A$5:$A$504,4,Pledges!$B$5:$B$504,A7)) | P7: =IF(5>Settings!$B$6,"",SUMIFS(Pledges!$E$5:$E$504,Pledges!$A$5:$A$504,5,Pledges!$B$5:$B$504,A7)) | Q7: =IF(6>Settings!$B$6,"",SUMIFS(Pledges!$E$5:$E$504,Pledges!$A$5:$A$504,6,Pledges!$B$5:$B$504,A7)) | R7: =IF(7>Settings!$B$6,"",SUMIFS(Pledges!$E$5:$E$504,Pledges!$A$5:$A$504,7,Pledges!$B$5:$B$504,A7)) | S7: =IF(8>Settings!$B$6,"",SUMIFS(Pledges!$E$5:$E$504,Pledges!$A$5:$A$504,8,Pledges!$B$5:$B$504,A7))
A8: =Steps!A8 | B8: =Steps!C8 | C8: =Steps!E8 | D8: =IF(1>Settings!$B$6,"",SUMIFS('Work log'!$F$5:$F$1004,'Work log'!$B$5:$B$1004,1,'Work log'!$C$5:$C$1004,A8,'Work log'!$L$5:$L$1004,">0")) | E8: =IF(2>Settings!$B$6,"",SUMIFS('Work log'!$F$5:$F$1004,'Work log'!$B$5:$B$1004,2,'Work log'!$C$5:$C$1004,A8,'Work log'!$L$5:$L$1004,">0")) | F8: =IF(3>Settings!$B$6,"",SUMIFS('Work log'!$F$5:$F$1004,'Work log'!$B$5:$B$1004,3,'Work log'!$C$5:$C$1004,A8,'Work log'!$L$5:$L$1004,">0")) | G8: =IF(4>Settings!$B$6,"",SUMIFS('Work log'!$F$5:$F$1004,'Work log'!$B$5:$B$1004,4,'Work log'!$C$5:$C$1004,A8,'Work log'!$L$5:$L$1004,">0")) | H8: =IF(5>Settings!$B$6,"",SUMIFS('Work log'!$F$5:$F$1004,'Work log'!$B$5:$B$1004,5,'Work log'!$C$5:$C$1004,A8,'Work log'!$L$5:$L$1004,">0")) | I8: =IF(6>Settings!$B$6,"",SUMIFS('Work log'!$F$5:$F$1004,'Work log'!$B$5:$B$1004,6,'Work log'!$C$5:$C$1004,A8,'Work log'!$L$5:$L$1004,">0")) | J8: =IF(7>Settings!$B$6,"",SUMIFS('Work log'!$F$5:$F$1004,'Work log'!$B$5:$B$1004,7,'Work log'!$C$5:$C$1004,A8,'Work log'!$L$5:$L$1004,">0")) | K8: =IF(8>Settings!$B$6,"",SUMIFS('Work log'!$F$5:$F$1004,'Work log'!$B$5:$B$1004,8,'Work log'!$C$5:$C$1004,A8,'Work log'!$L$5:$L$1004,">0")) | L8: =IF(1>Settings!$B$6,"",SUMIFS(Pledges!$E$5:$E$504,Pledges!$A$5:$A$504,1,Pledges!$B$5:$B$504,A8)) | M8: =IF(2>Settings!$B$6,"",SUMIFS(Pledges!$E$5:$E$504,Pledges!$A$5:$A$504,2,Pledges!$B$5:$B$504,A8)) | N8: =IF(3>Settings!$B$6,"",SUMIFS(Pledges!$E$5:$E$504,Pledges!$A$5:$A$504,3,Pledges!$B$5:$B$504,A8)) | O8: =IF(4>Settings!$B$6,"",SUMIFS(Pledges!$E$5:$E$504,Pledges!$A$5:$A$504,4,Pledges!$B$5:$B$504,A8)) | P8: =IF(5>Settings!$B$6,"",SUMIFS(Pledges!$E$5:$E$504,Pledges!$A$5:$A$504,5,Pledges!$B$5:$B$504,A8)) | Q8: =IF(6>Settings!$B$6,"",SUMIFS(Pledges!$E$5:$E$504,Pledges!$A$5:$A$504,6,Pledges!$B$5:$B$504,A8)) | R8: =IF(7>Settings!$B$6,"",SUMIFS(Pledges!$E$5:$E$504,Pledges!$A$5:$A$504,7,Pledges!$B$5:$B$504,A8)) | S8: =IF(8>Settings!$B$6,"",SUMIFS(Pledges!$E$5:$E$504,Pledges!$A$5:$A$504,8,Pledges!$B$5:$B$504,A8))
A9: =Steps!A9 | B9: =Steps!C9 | C9: =Steps!E9 | D9: =IF(1>Settings!$B$6,"",SUMIFS('Work log'!$F$5:$F$1004,'Work log'!$B$5:$B$1004,1,'Work log'!$C$5:$C$1004,A9,'Work log'!$L$5:$L$1004,">0")) | E9: =IF(2>Settings!$B$6,"",SUMIFS('Work log'!$F$5:$F$1004,'Work log'!$B$5:$B$1004,2,'Work log'!$C$5:$C$1004,A9,'Work log'!$L$5:$L$1004,">0")) | F9: =IF(3>Settings!$B$6,"",SUMIFS('Work log'!$F$5:$F$1004,'Work log'!$B$5:$B$1004,3,'Work log'!$C$5:$C$1004,A9,'Work log'!$L$5:$L$1004,">0")) | G9: =IF(4>Settings!$B$6,"",SUMIFS('Work log'!$F$5:$F$1004,'Work log'!$B$5:$B$1004,4,'Work log'!$C$5:$C$1004,A9,'Work log'!$L$5:$L$1004,">0")) | H9: =IF(5>Settings!$B$6,"",SUMIFS('Work log'!$F$5:$F$1004,'Work log'!$B$5:$B$1004,5,'Work log'!$C$5:$C$1004,A9,'Work log'!$L$5:$L$1004,">0")) | I9: =IF(6>Settings!$B$6,"",SUMIFS('Work log'!$F$5:$F$1004,'Work log'!$B$5:$B$1004,6,'Work log'!$C$5:$C$1004,A9,'Work log'!$L$5:$L$1004,">0")) | J9: =IF(7>Settings!$B$6,"",SUMIFS('Work log'!$F$5:$F$1004,'Work log'!$B$5:$B$1004,7,'Work log'!$C$5:$C$1004,A9,'Work log'!$L$5:$L$1004,">0")) | K9: =IF(8>Settings!$B$6,"",SUMIFS('Work log'!$F$5:$F$1004,'Work log'!$B$5:$B$1004,8,'Work log'!$C$5:$C$1004,A9,'Work log'!$L$5:$L$1004,">0")) | L9: =IF(1>Settings!$B$6,"",SUMIFS(Pledges!$E$5:$E$504,Pledges!$A$5:$A$504,1,Pledges!$B$5:$B$504,A9)) | M9: =IF(2>Settings!$B$6,"",SUMIFS(Pledges!$E$5:$E$504,Pledges!$A$5:$A$504,2,Pledges!$B$5:$B$504,A9)) | N9: =IF(3>Settings!$B$6,"",SUMIFS(Pledges!$E$5:$E$504,Pledges!$A$5:$A$504,3,Pledges!$B$5:$B$504,A9)) | O9: =IF(4>Settings!$B$6,"",SUMIFS(Pledges!$E$5:$E$504,Pledges!$A$5:$A$504,4,Pledges!$B$5:$B$504,A9)) | P9: =IF(5>Settings!$B$6,"",SUMIFS(Pledges!$E$5:$E$504,Pledges!$A$5:$A$504,5,Pledges!$B$5:$B$504,A9)) | Q9: =IF(6>Settings!$B$6,"",SUMIFS(Pledges!$E$5:$E$504,Pledges!$A$5:$A$504,6,Pledges!$B$5:$B$504,A9)) | R9: =IF(7>Settings!$B$6,"",SUMIFS(Pledges!$E$5:$E$504,Pledges!$A$5:$A$504,7,Pledges!$B$5:$B$504,A9)) | S9: =IF(8>Settings!$B$6,"",SUMIFS(Pledges!$E$5:$E$504,Pledges!$A$5:$A$504,8,Pledges!$B$5:$B$504,A9))
A10: =Steps!A10 | B10: =Steps!C10 | C10: =Steps!E10 | D10: =IF(1>Settings!$B$6,"",SUMIFS('Work log'!$F$5:$F$1004,'Work log'!$B$5:$B$1004,1,'Work log'!$C$5:$C$1004,A10,'Work log'!$L$5:$L$1004,">0")) | E10: =IF(2>Settings!$B$6,"",SUMIFS('Work log'!$F$5:$F$1004,'Work log'!$B$5:$B$1004,2,'Work log'!$C$5:$C$1004,A10,'Work log'!$L$5:$L$1004,">0")) | F10: =IF(3>Settings!$B$6,"",SUMIFS('Work log'!$F$5:$F$1004,'Work log'!$B$5:$B$1004,3,'Work log'!$C$5:$C$1004,A10,'Work log'!$L$5:$L$1004,">0")) | G10: =IF(4>Settings!$B$6,"",SUMIFS('Work log'!$F$5:$F$1004,'Work log'!$B$5:$B$1004,4,'Work log'!$C$5:$C$1004,A10,'Work log'!$L$5:$L$1004,">0")) | H10: =IF(5>Settings!$B$6,"",SUMIFS('Work log'!$F$5:$F$1004,'Work log'!$B$5:$B$1004,5,'Work log'!$C$5:$C$1004,A10,'Work log'!$L$5:$L$1004,">0")) | I10: =IF(6>Settings!$B$6,"",SUMIFS('Work log'!$F$5:$F$1004,'Work log'!$B$5:$B$1004,6,'Work log'!$C$5:$C$1004,A10,'Work log'!$L$5:$L$1004,">0")) | J10: =IF(7>Settings!$B$6,"",SUMIFS('Work log'!$F$5:$F$1004,'Work log'!$B$5:$B$1004,7,'Work log'!$C$5:$C$1004,A10,'Work log'!$L$5:$L$1004,">0")) | K10: =IF(8>Settings!$B$6,"",SUMIFS('Work log'!$F$5:$F$1004,'Work log'!$B$5:$B$1004,8,'Work log'!$C$5:$C$1004,A10,'Work log'!$L$5:$L$1004,">0")) | L10: =IF(1>Settings!$B$6,"",SUMIFS(Pledges!$E$5:$E$504,Pledges!$A$5:$A$504,1,Pledges!$B$5:$B$504,A10)) | M10: =IF(2>Settings!$B$6,"",SUMIFS(Pledges!$E$5:$E$504,Pledges!$A$5:$A$504,2,Pledges!$B$5:$B$504,A10)) | N10: =IF(3>Settings!$B$6,"",SUMIFS(Pledges!$E$5:$E$504,Pledges!$A$5:$A$504,3,Pledges!$B$5:$B$504,A10)) | O10: =IF(4>Settings!$B$6,"",SUMIFS(Pledges!$E$5:$E$504,Pledges!$A$5:$A$504,4,Pledges!$B$5:$B$504,A10)) | P10: =IF(5>Settings!$B$6,"",SUMIFS(Pledges!$E$5:$E$504,Pledges!$A$5:$A$504,5,Pledges!$B$5:$B$504,A10)) | Q10: =IF(6>Settings!$B$6,"",SUMIFS(Pledges!$E$5:$E$504,Pledges!$A$5:$A$504,6,Pledges!$B$5:$B$504,A10)) | R10: =IF(7>Settings!$B$6,"",SUMIFS(Pledges!$E$5:$E$504,Pledges!$A$5:$A$504,7,Pledges!$B$5:$B$504,A10)) | S10: =IF(8>Settings!$B$6,"",SUMIFS(Pledges!$E$5:$E$504,Pledges!$A$5:$A$504,8,Pledges!$B$5:$B$504,A10))
A11: =Steps!A11 | B11: =Steps!C11 | C11: =Steps!E11 | D11: =IF(1>Settings!$B$6,"",SUMIFS('Work log'!$F$5:$F$1004,'Work log'!$B$5:$B$1004,1,'Work log'!$C$5:$C$1004,A11,'Work log'!$L$5:$L$1004,">0")) | E11: =IF(2>Settings!$B$6,"",SUMIFS('Work log'!$F$5:$F$1004,'Work log'!$B$5:$B$1004,2,'Work log'!$C$5:$C$1004,A11,'Work log'!$L$5:$L$1004,">0")) | F11: =IF(3>Settings!$B$6,"",SUMIFS('Work log'!$F$5:$F$1004,'Work log'!$B$5:$B$1004,3,'Work log'!$C$5:$C$1004,A11,'Work log'!$L$5:$L$1004,">0")) | G11: =IF(4>Settings!$B$6,"",SUMIFS('Work log'!$F$5:$F$1004,'Work log'!$B$5:$B$1004,4,'Work log'!$C$5:$C$1004,A11,'Work log'!$L$5:$L$1004,">0")) | H11: =IF(5>Settings!$B$6,"",SUMIFS('Work log'!$F$5:$F$1004,'Work log'!$B$5:$B$1004,5,'Work log'!$C$5:$C$1004,A11,'Work log'!$L$5:$L$1004,">0")) | I11: =IF(6>Settings!$B$6,"",SUMIFS('Work log'!$F$5:$F$1004,'Work log'!$B$5:$B$1004,6,'Work log'!$C$5:$C$1004,A11,'Work log'!$L$5:$L$1004,">0")) | J11: =IF(7>Settings!$B$6,"",SUMIFS('Work log'!$F$5:$F$1004,'Work log'!$B$5:$B$1004,7,'Work log'!$C$5:$C$1004,A11,'Work log'!$L$5:$L$1004,">0")) | K11: =IF(8>Settings!$B$6,"",SUMIFS('Work log'!$F$5:$F$1004,'Work log'!$B$5:$B$1004,8,'Work log'!$C$5:$C$1004,A11,'Work log'!$L$5:$L$1004,">0")) | L11: =IF(1>Settings!$B$6,"",SUMIFS(Pledges!$E$5:$E$504,Pledges!$A$5:$A$504,1,Pledges!$B$5:$B$504,A11)) | M11: =IF(2>Settings!$B$6,"",SUMIFS(Pledges!$E$5:$E$504,Pledges!$A$5:$A$504,2,Pledges!$B$5:$B$504,A11)) | N11: =IF(3>Settings!$B$6,"",SUMIFS(Pledges!$E$5:$E$504,Pledges!$A$5:$A$504,3,Pledges!$B$5:$B$504,A11)) | O11: =IF(4>Settings!$B$6,"",SUMIFS(Pledges!$E$5:$E$504,Pledges!$A$5:$A$504,4,Pledges!$B$5:$B$504,A11)) | P11: =IF(5>Settings!$B$6,"",SUMIFS(Pledges!$E$5:$E$504,Pledges!$A$5:$A$504,5,Pledges!$B$5:$B$504,A11)) | Q11: =IF(6>Settings!$B$6,"",SUMIFS(Pledges!$E$5:$E$504,Pledges!$A$5:$A$504,6,Pledges!$B$5:$B$504,A11)) | R11: =IF(7>Settings!$B$6,"",SUMIFS(Pledges!$E$5:$E$504,Pledges!$A$5:$A$504,7,Pledges!$B$5:$B$504,A11)) | S11: =IF(8>Settings!$B$6,"",SUMIFS(Pledges!$E$5:$E$504,Pledges!$A$5:$A$504,8,Pledges!$B$5:$B$504,A11))
A12: =Steps!A12 | B12: =Steps!C12 | C12: =Steps!E12 | D12: =IF(1>Settings!$B$6,"",SUMIFS('Work log'!$F$5:$F$1004,'Work log'!$B$5:$B$1004,1,'Work log'!$C$5:$C$1004,A12,'Work log'!$L$5:$L$1004,">0")) | E12: =IF(2>Settings!$B$6,"",SUMIFS('Work log'!$F$5:$F$1004,'Work log'!$B$5:$B$1004,2,'Work log'!$C$5:$C$1004,A12,'Work log'!$L$5:$L$1004,">0")) | F12: =IF(3>Settings!$B$6,"",SUMIFS('Work log'!$F$5:$F$1004,'Work log'!$B$5:$B$1004,3,'Work log'!$C$5:$C$1004,A12,'Work log'!$L$5:$L$1004,">0")) | G12: =IF(4>Settings!$B$6,"",SUMIFS('Work log'!$F$5:$F$1004,'Work log'!$B$5:$B$1004,4,'Work log'!$C$5:$C$1004,A12,'Work log'!$L$5:$L$1004,">0")) | H12: =IF(5>Settings!$B$6,"",SUMIFS('Work log'!$F$5:$F$1004,'Work log'!$B$5:$B$1004,5,'Work log'!$C$5:$C$1004,A12,'Work log'!$L$5:$L$1004,">0")) | I12: =IF(6>Settings!$B$6,"",SUMIFS('Work log'!$F$5:$F$1004,'Work log'!$B$5:$B$1004,6,'Work log'!$C$5:$C$1004,A12,'Work log'!$L$5:$L$1004,">0")) | J12: =IF(7>Settings!$B$6,"",SUMIFS('Work log'!$F$5:$F$1004,'Work log'!$B$5:$B$1004,7,'Work log'!$C$5:$C$1004,A12,'Work log'!$L$5:$L$1004,">0")) | K12: =IF(8>Settings!$B$6,"",SUMIFS('Work log'!$F$5:$F$1004,'Work log'!$B$5:$B$1004,8,'Work log'!$C$5:$C$1004,A12,'Work log'!$L$5:$L$1004,">0")) | L12: =IF(1>Settings!$B$6,"",SUMIFS(Pledges!$E$5:$E$504,Pledges!$A$5:$A$504,1,Pledges!$B$5:$B$504,A12)) | M12: =IF(2>Settings!$B$6,"",SUMIFS(Pledges!$E$5:$E$504,Pledges!$A$5:$A$504,2,Pledges!$B$5:$B$504,A12)) | N12: =IF(3>Settings!$B$6,"",SUMIFS(Pledges!$E$5:$E$504,Pledges!$A$5:$A$504,3,Pledges!$B$5:$B$504,A12)) | O12: =IF(4>Settings!$B$6,"",SUMIFS(Pledges!$E$5:$E$504,Pledges!$A$5:$A$504,4,Pledges!$B$5:$B$504,A12)) | P12: =IF(5>Settings!$B$6,"",SUMIFS(Pledges!$E$5:$E$504,Pledges!$A$5:$A$504,5,Pledges!$B$5:$B$504,A12)) | Q12: =IF(6>Settings!$B$6,"",SUMIFS(Pledges!$E$5:$E$504,Pledges!$A$5:$A$504,6,Pledges!$B$5:$B$504,A12)) | R12: =IF(7>Settings!$B$6,"",SUMIFS(Pledges!$E$5:$E$504,Pledges!$A$5:$A$504,7,Pledges!$B$5:$B$504,A12)) | S12: =IF(8>Settings!$B$6,"",SUMIFS(Pledges!$E$5:$E$504,Pledges!$A$5:$A$504,8,Pledges!$B$5:$B$504,A12))
A13: =Steps!A13 | B13: =Steps!C13 | C13: =Steps!E13 | D13: =IF(1>Settings!$B$6,"",SUMIFS('Work log'!$F$5:$F$1004,'Work log'!$B$5:$B$1004,1,'Work log'!$C$5:$C$1004,A13,'Work log'!$L$5:$L$1004,">0")) | E13: =IF(2>Settings!$B$6,"",SUMIFS('Work log'!$F$5:$F$1004,'Work log'!$B$5:$B$1004,2,'Work log'!$C$5:$C$1004,A13,'Work log'!$L$5:$L$1004,">0")) | F13: =IF(3>Settings!$B$6,"",SUMIFS('Work log'!$F$5:$F$1004,'Work log'!$B$5:$B$1004,3,'Work log'!$C$5:$C$1004,A13,'Work log'!$L$5:$L$1004,">0")) | G13: =IF(4>Settings!$B$6,"",SUMIFS('Work log'!$F$5:$F$1004,'Work log'!$B$5:$B$1004,4,'Work log'!$C$5:$C$1004,A13,'Work log'!$L$5:$L$1004,">0")) | H13: =IF(5>Settings!$B$6,"",SUMIFS('Work log'!$F$5:$F$1004,'Work log'!$B$5:$B$1004,5,'Work log'!$C$5:$C$1004,A13,'Work log'!$L$5:$L$1004,">0")) | I13: =IF(6>Settings!$B$6,"",SUMIFS('Work log'!$F$5:$F$1004,'Work log'!$B$5:$B$1004,6,'Work log'!$C$5:$C$1004,A13,'Work log'!$L$5:$L$1004,">0")) | J13: =IF(7>Settings!$B$6,"",SUMIFS('Work log'!$F$5:$F$1004,'Work log'!$B$5:$B$1004,7,'Work log'!$C$5:$C$1004,A13,'Work log'!$L$5:$L$1004,">0")) | K13: =IF(8>Settings!$B$6,"",SUMIFS('Work log'!$F$5:$F$1004,'Work log'!$B$5:$B$1004,8,'Work log'!$C$5:$C$1004,A13,'Work log'!$L$5:$L$1004,">0")) | L13: =IF(1>Settings!$B$6,"",SUMIFS(Pledges!$E$5:$E$504,Pledges!$A$5:$A$504,1,Pledges!$B$5:$B$504,A13)) | M13: =IF(2>Settings!$B$6,"",SUMIFS(Pledges!$E$5:$E$504,Pledges!$A$5:$A$504,2,Pledges!$B$5:$B$504,A13)) | N13: =IF(3>Settings!$B$6,"",SUMIFS(Pledges!$E$5:$E$504,Pledges!$A$5:$A$504,3,Pledges!$B$5:$B$504,A13)) | O13: =IF(4>Settings!$B$6,"",SUMIFS(Pledges!$E$5:$E$504,Pledges!$A$5:$A$504,4,Pledges!$B$5:$B$504,A13)) | P13: =IF(5>Settings!$B$6,"",SUMIFS(Pledges!$E$5:$E$504,Pledges!$A$5:$A$504,5,Pledges!$B$5:$B$504,A13)) | Q13: =IF(6>Settings!$B$6,"",SUMIFS(Pledges!$E$5:$E$504,Pledges!$A$5:$A$504,6,Pledges!$B$5:$B$504,A13)) | R13: =IF(7>Settings!$B$6,"",SUMIFS(Pledges!$E$5:$E$504,Pledges!$A$5:$A$504,7,Pledges!$B$5:$B$504,A13)) | S13: =IF(8>Settings!$B$6,"",SUMIFS(Pledges!$E$5:$E$504,Pledges!$A$5:$A$504,8,Pledges!$B$5:$B$504,A13))
A14: =Steps!A14 | B14: =Steps!C14 | C14: =Steps!E14 | D14: =IF(1>Settings!$B$6,"",SUMIFS('Work log'!$F$5:$F$1004,'Work log'!$B$5:$B$1004,1,'Work log'!$C$5:$C$1004,A14,'Work log'!$L$5:$L$1004,">0")) | E14: =IF(2>Settings!$B$6,"",SUMIFS('Work log'!$F$5:$F$1004,'Work log'!$B$5:$B$1004,2,'Work log'!$C$5:$C$1004,A14,'Work log'!$L$5:$L$1004,">0")) | F14: =IF(3>Settings!$B$6,"",SUMIFS('Work log'!$F$5:$F$1004,'Work log'!$B$5:$B$1004,3,'Work log'!$C$5:$C$1004,A14,'Work log'!$L$5:$L$1004,">0")) | G14: =IF(4>Settings!$B$6,"",SUMIFS('Work log'!$F$5:$F$1004,'Work log'!$B$5:$B$1004,4,'Work log'!$C$5:$C$1004,A14,'Work log'!$L$5:$L$1004,">0")) | H14: =IF(5>Settings!$B$6,"",SUMIFS('Work log'!$F$5:$F$1004,'Work log'!$B$5:$B$1004,5,'Work log'!$C$5:$C$1004,A14,'Work log'!$L$5:$L$1004,">0")) | I14: =IF(6>Settings!$B$6,"",SUMIFS('Work log'!$F$5:$F$1004,'Work log'!$B$5:$B$1004,6,'Work log'!$C$5:$C$1004,A14,'Work log'!$L$5:$L$1004,">0")) | J14: =IF(7>Settings!$B$6,"",SUMIFS('Work log'!$F$5:$F$1004,'Work log'!$B$5:$B$1004,7,'Work log'!$C$5:$C$1004,A14,'Work log'!$L$5:$L$1004,">0")) | K14: =IF(8>Settings!$B$6,"",SUMIFS('Work log'!$F$5:$F$1004,'Work log'!$B$5:$B$1004,8,'Work log'!$C$5:$C$1004,A14,'Work log'!$L$5:$L$1004,">0")) | L14: =IF(1>Settings!$B$6,"",SUMIFS(Pledges!$E$5:$E$504,Pledges!$A$5:$A$504,1,Pledges!$B$5:$B$504,A14)) | M14: =IF(2>Settings!$B$6,"",SUMIFS(Pledges!$E$5:$E$504,Pledges!$A$5:$A$504,2,Pledges!$B$5:$B$504,A14)) | N14: =IF(3>Settings!$B$6,"",SUMIFS(Pledges!$E$5:$E$504,Pledges!$A$5:$A$504,3,Pledges!$B$5:$B$504,A14)) | O14: =IF(4>Settings!$B$6,"",SUMIFS(Pledges!$E$5:$E$504,Pledges!$A$5:$A$504,4,Pledges!$B$5:$B$504,A14)) | P14: =IF(5>Settings!$B$6,"",SUMIFS(Pledges!$E$5:$E$504,Pledges!$A$5:$A$504,5,Pledges!$B$5:$B$504,A14)) | Q14: =IF(6>Settings!$B$6,"",SUMIFS(Pledges!$E$5:$E$504,Pledges!$A$5:$A$504,6,Pledges!$B$5:$B$504,A14)) | R14: =IF(7>Settings!$B$6,"",SUMIFS(Pledges!$E$5:$E$504,Pledges!$A$5:$A$504,7,Pledges!$B$5:$B$504,A14)) | S14: =IF(8>Settings!$B$6,"",SUMIFS(Pledges!$E$5:$E$504,Pledges!$A$5:$A$504,8,Pledges!$B$5:$B$504,A14))
A15: =Steps!A15 | B15: =Steps!C15 | C15: =Steps!E15 | D15: =IF(1>Settings!$B$6,"",SUMIFS('Work log'!$F$5:$F$1004,'Work log'!$B$5:$B$1004,1,'Work log'!$C$5:$C$1004,A15,'Work log'!$L$5:$L$1004,">0")) | E15: =IF(2>Settings!$B$6,"",SUMIFS('Work log'!$F$5:$F$1004,'Work log'!$B$5:$B$1004,2,'Work log'!$C$5:$C$1004,A15,'Work log'!$L$5:$L$1004,">0")) | F15: =IF(3>Settings!$B$6,"",SUMIFS('Work log'!$F$5:$F$1004,'Work log'!$B$5:$B$1004,3,'Work log'!$C$5:$C$1004,A15,'Work log'!$L$5:$L$1004,">0")) | G15: =IF(4>Settings!$B$6,"",SUMIFS('Work log'!$F$5:$F$1004,'Work log'!$B$5:$B$1004,4,'Work log'!$C$5:$C$1004,A15,'Work log'!$L$5:$L$1004,">0")) | H15: =IF(5>Settings!$B$6,"",SUMIFS('Work log'!$F$5:$F$1004,'Work log'!$B$5:$B$1004,5,'Work log'!$C$5:$C$1004,A15,'Work log'!$L$5:$L$1004,">0")) | I15: =IF(6>Settings!$B$6,"",SUMIFS('Work log'!$F$5:$F$1004,'Work log'!$B$5:$B$1004,6,'Work log'!$C$5:$C$1004,A15,'Work log'!$L$5:$L$1004,">0")) | J15: =IF(7>Settings!$B$6,"",SUMIFS('Work log'!$F$5:$F$1004,'Work log'!$B$5:$B$1004,7,'Work log'!$C$5:$C$1004,A15,'Work log'!$L$5:$L$1004,">0")) | K15: =IF(8>Settings!$B$6,"",SUMIFS('Work log'!$F$5:$F$1004,'Work log'!$B$5:$B$1004,8,'Work log'!$C$5:$C$1004,A15,'Work log'!$L$5:$L$1004,">0")) | L15: =IF(1>Settings!$B$6,"",SUMIFS(Pledges!$E$5:$E$504,Pledges!$A$5:$A$504,1,Pledges!$B$5:$B$504,A15)) | M15: =IF(2>Settings!$B$6,"",SUMIFS(Pledges!$E$5:$E$504,Pledges!$A$5:$A$504,2,Pledges!$B$5:$B$504,A15)) | N15: =IF(3>Settings!$B$6,"",SUMIFS(Pledges!$E$5:$E$504,Pledges!$A$5:$A$504,3,Pledges!$B$5:$B$504,A15)) | O15: =IF(4>Settings!$B$6,"",SUMIFS(Pledges!$E$5:$E$504,Pledges!$A$5:$A$504,4,Pledges!$B$5:$B$504,A15)) | P15: =IF(5>Settings!$B$6,"",SUMIFS(Pledges!$E$5:$E$504,Pledges!$A$5:$A$504,5,Pledges!$B$5:$B$504,A15)) | Q15: =IF(6>Settings!$B$6,"",SUMIFS(Pledges!$E$5:$E$504,Pledges!$A$5:$A$504,6,Pledges!$B$5:$B$504,A15)) | R15: =IF(7>Settings!$B$6,"",SUMIFS(Pledges!$E$5:$E$504,Pledges!$A$5:$A$504,7,Pledges!$B$5:$B$504,A15)) | S15: =IF(8>Settings!$B$6,"",SUMIFS(Pledges!$E$5:$E$504,Pledges!$A$5:$A$504,8,Pledges!$B$5:$B$504,A15))
A16: =Steps!A16 | B16: =Steps!C16 | C16: =Steps!E16 | D16: =IF(1>Settings!$B$6,"",SUMIFS('Work log'!$F$5:$F$1004,'Work log'!$B$5:$B$1004,1,'Work log'!$C$5:$C$1004,A16,'Work log'!$L$5:$L$1004,">0")) | E16: =IF(2>Settings!$B$6,"",SUMIFS('Work log'!$F$5:$F$1004,'Work log'!$B$5:$B$1004,2,'Work log'!$C$5:$C$1004,A16,'Work log'!$L$5:$L$1004,">0")) | F16: =IF(3>Settings!$B$6,"",SUMIFS('Work log'!$F$5:$F$1004,'Work log'!$B$5:$B$1004,3,'Work log'!$C$5:$C$1004,A16,'Work log'!$L$5:$L$1004,">0")) | G16: =IF(4>Settings!$B$6,"",SUMIFS('Work log'!$F$5:$F$1004,'Work log'!$B$5:$B$1004,4,'Work log'!$C$5:$C$1004,A16,'Work log'!$L$5:$L$1004,">0")) | H16: =IF(5>Settings!$B$6,"",SUMIFS('Work log'!$F$5:$F$1004,'Work log'!$B$5:$B$1004,5,'Work log'!$C$5:$C$1004,A16,'Work log'!$L$5:$L$1004,">0")) | I16: =IF(6>Settings!$B$6,"",SUMIFS('Work log'!$F$5:$F$1004,'Work log'!$B$5:$B$1004,6,'Work log'!$C$5:$C$1004,A16,'Work log'!$L$5:$L$1004,">0")) | J16: =IF(7>Settings!$B$6,"",SUMIFS('Work log'!$F$5:$F$1004,'Work log'!$B$5:$B$1004,7,'Work log'!$C$5:$C$1004,A16,'Work log'!$L$5:$L$1004,">0")) | K16: =IF(8>Settings!$B$6,"",SUMIFS('Work log'!$F$5:$F$1004,'Work log'!$B$5:$B$1004,8,'Work log'!$C$5:$C$1004,A16,'Work log'!$L$5:$L$1004,">0")) | L16: =IF(1>Settings!$B$6,"",SUMIFS(Pledges!$E$5:$E$504,Pledges!$A$5:$A$504,1,Pledges!$B$5:$B$504,A16)) | M16: =IF(2>Settings!$B$6,"",SUMIFS(Pledges!$E$5:$E$504,Pledges!$A$5:$A$504,2,Pledges!$B$5:$B$504,A16)) | N16: =IF(3>Settings!$B$6,"",SUMIFS(Pledges!$E$5:$E$504,Pledges!$A$5:$A$504,3,Pledges!$B$5:$B$504,A16)) | O16: =IF(4>Settings!$B$6,"",SUMIFS(Pledges!$E$5:$E$504,Pledges!$A$5:$A$504,4,Pledges!$B$5:$B$504,A16)) | P16: =IF(5>Settings!$B$6,"",SUMIFS(Pledges!$E$5:$E$504,Pledges!$A$5:$A$504,5,Pledges!$B$5:$B$504,A16)) | Q16: =IF(6>Settings!$B$6,"",SUMIFS(Pledges!$E$5:$E$504,Pledges!$A$5:$A$504,6,Pledges!$B$5:$B$504,A16)) | R16: =IF(7>Settings!$B$6,"",SUMIFS(Pledges!$E$5:$E$504,Pledges!$A$5:$A$504,7,Pledges!$B$5:$B$504,A16)) | S16: =IF(8>Settings!$B$6,"",SUMIFS(Pledges!$E$5:$E$504,Pledges!$A$5:$A$504,8,Pledges!$B$5:$B$504,A16))
... A62: =Steps!A62 | B62: =Steps!C62 | C62: =Steps!E62 | D62: =IF(1>Settings!$B$6,"",SUMIFS('Work log'!$F$5:$F$1004,'Work log'!$B$5:$B$1004,1,'Work log'!$C$5:$C$1004,A62,'Work log'!$L$5:$L$1004,">0")) | E62: =IF(2>Settings!$B$6,"",SUMIFS('Work log'!$F$5:$F$1004,'Work log'!$B$5:$B$1004,2,'Work log'!$C$5:$C$1004,A62,'Work log'!$L$5:$L$1004,">0")) | F62: =IF(3>Settings!$B$6,"",SUMIFS('Work log'!$F$5:$F$1004,'Work log'!$B$5:$B$1004,3,'Work log'!$C$5:$C$1004,A62,'Work log'!$L$5:$L$1004,">0")) | G62: =IF(4>Settings!$B$6,"",SUMIFS('Work log'!$F$5:$F$1004,'Work log'!$B$5:$B$1004,4,'Work log'!$C$5:$C$1004,A62,'Work log'!$L$5:$L$1004,">0")) | H62: =IF(5>Settings!$B$6,"",SUMIFS('Work log'!$F$5:$F$1004,'Work log'!$B$5:$B$1004,5,'Work log'!$C$5:$C$1004,A62,'Work log'!$L$5:$L$1004,">0")) | I62: =IF(6>Settings!$B$6,"",SUMIFS('Work log'!$F$5:$F$1004,'Work log'!$B$5:$B$1004,6,'Work log'!$C$5:$C$1004,A62,'Work log'!$L$5:$L$1004,">0")) | J62: =IF(7>Settings!$B$6,"",SUMIFS('Work log'!$F$5:$F$1004,'Work log'!$B$5:$B$1004,7,'Work log'!$C$5:$C$1004,A62,'Work log'!$L$5:$L$1004,">0")) | K62: =IF(8>Settings!$B$6,"",SUMIFS('Work log'!$F$5:$F$1004,'Work log'!$B$5:$B$1004,8,'Work log'!$C$5:$C$1004,A62,'Work log'!$L$5:$L$1004,">0")) | L62: =IF(1>Settings!$B$6,"",SUMIFS(Pledges!$E$5:$E$504,Pledges!$A$5:$A$504,1,Pledges!$B$5:$B$504,A62)) | M62: =IF(2>Settings!$B$6,"",SUMIFS(Pledges!$E$5:$E$504,Pledges!$A$5:$A$504,2,Pledges!$B$5:$B$504,A62)) | N62: =IF(3>Settings!$B$6,"",SUMIFS(Pledges!$E$5:$E$504,Pledges!$A$5:$A$504,3,Pledges!$B$5:$B$504,A62)) | O62: =IF(4>Settings!$B$6,"",SUMIFS(Pledges!$E$5:$E$504,Pledges!$A$5:$A$504,4,Pledges!$B$5:$B$504,A62)) | P62: =IF(5>Settings!$B$6,"",SUMIFS(Pledges!$E$5:$E$504,Pledges!$A$5:$A$504,5,Pledges!$B$5:$B$504,A62)) | Q62: =IF(6>Settings!$B$6,"",SUMIFS(Pledges!$E$5:$E$504,Pledges!$A$5:$A$504,6,Pledges!$B$5:$B$504,A62)) | R62: =IF(7>Settings!$B$6,"",SUMIFS(Pledges!$E$5:$E$504,Pledges!$A$5:$A$504,7,Pledges!$B$5:$B$504,A62)) | S62: =IF(8>Settings!$B$6,"",SUMIFS(Pledges!$E$5:$E$504,Pledges!$A$5:$A$504,8,Pledges!$B$5:$B$504,A62))
B63: Value done and signed off ($) | D63: =IF(1>Settings!$B$6,"",SUMPRODUCT($C$5:$C$62,D5:D62)) | E63: =IF(2>Settings!$B$6,"",SUMPRODUCT($C$5:$C$62,E5:E62)) | F63: =IF(3>Settings!$B$6,"",SUMPRODUCT($C$5:$C$62,F5:F62)) | G63: =IF(4>Settings!$B$6,"",SUMPRODUCT($C$5:$C$62,G5:G62)) | H63: =IF(5>Settings!$B$6,"",SUMPRODUCT($C$5:$C$62,H5:H62)) | I63: =IF(6>Settings!$B$6,"",SUMPRODUCT($C$5:$C$62,I5:I62)) | J63: =IF(7>Settings!$B$6,"",SUMPRODUCT($C$5:$C$62,J5:J62)) | K63: =IF(8>Settings!$B$6,"",SUMPRODUCT($C$5:$C$62,K5:K62))
B64: Share of the build done | D64: =IF(1>Settings!$B$6,"",D63/Steps!$E$63) | E64: =IF(2>Settings!$B$6,"",E63/Steps!$E$63) | F64: =IF(3>Settings!$B$6,"",F63/Steps!$E$63) | G64: =IF(4>Settings!$B$6,"",G63/Steps!$E$63) | H64: =IF(5>Settings!$B$6,"",H63/Steps!$E$63) | I64: =IF(6>Settings!$B$6,"",I63/Steps!$E$63) | J64: =IF(7>Settings!$B$6,"",J63/Steps!$E$63) | K64: =IF(8>Settings!$B$6,"",K63/Steps!$E$63)

Sheet Ownership
A1: Credit and ownership
A2: Counted credit = (work + pro overrun + contributions) x the share kept. Ownership = counted credit / total.
A4: Member | B4: Status | C4: Pledged ($) | D4: Work credit ($) | E4: Pro overrun as cash ($) | F4: Contributions ($) | G4: Total credit ($) | H4: Share kept | I4: Counted credit ($) | J4: Ownership | K4: Pledged work done
A5: =IF(Members!B5="","",Members!B5) | B5: =IF(A5="","",Members!E5) | C5: =IF(A5="",0,SUMIFS(Pledges!$H$5:$H$504,Pledges!$D$5:$D$504,A5)) | D5: =IF(A5="",0,SUMIFS('Work log'!$L$5:$L$1004,'Work log'!$E$5:$E$1004,A5)) | E5: =IF(A5="",0,SUMIFS('Work log'!$M$5:$M$1004,'Work log'!$E$5:$E$1004,A5)) | F5: =IF(A5="",0,SUMIFS(Contributions!$G$5:$G$304,Contributions!$B$5:$B$304,A5)) | G5: =D5+E5+F5 | H5: =IF(A5="","",IF(B5="Withdrawn",Settings!$B$8,1)) | I5: =IF(A5="",0,G5*H5) | J5: =IF(OR(A5="",$I$17=0),"",I5/$I$17) | K5: =IF(OR(A5="",C5=0),"",D5/C5)
A6: =IF(Members!B6="","",Members!B6) | B6: =IF(A6="","",Members!E6) | C6: =IF(A6="",0,SUMIFS(Pledges!$H$5:$H$504,Pledges!$D$5:$D$504,A6)) | D6: =IF(A6="",0,SUMIFS('Work log'!$L$5:$L$1004,'Work log'!$E$5:$E$1004,A6)) | E6: =IF(A6="",0,SUMIFS('Work log'!$M$5:$M$1004,'Work log'!$E$5:$E$1004,A6)) | F6: =IF(A6="",0,SUMIFS(Contributions!$G$5:$G$304,Contributions!$B$5:$B$304,A6)) | G6: =D6+E6+F6 | H6: =IF(A6="","",IF(B6="Withdrawn",Settings!$B$8,1)) | I6: =IF(A6="",0,G6*H6) | J6: =IF(OR(A6="",$I$17=0),"",I6/$I$17) | K6: =IF(OR(A6="",C6=0),"",D6/C6)
A7: =IF(Members!B7="","",Members!B7) | B7: =IF(A7="","",Members!E7) | C7: =IF(A7="",0,SUMIFS(Pledges!$H$5:$H$504,Pledges!$D$5:$D$504,A7)) | D7: =IF(A7="",0,SUMIFS('Work log'!$L$5:$L$1004,'Work log'!$E$5:$E$1004,A7)) | E7: =IF(A7="",0,SUMIFS('Work log'!$M$5:$M$1004,'Work log'!$E$5:$E$1004,A7)) | F7: =IF(A7="",0,SUMIFS(Contributions!$G$5:$G$304,Contributions!$B$5:$B$304,A7)) | G7: =D7+E7+F7 | H7: =IF(A7="","",IF(B7="Withdrawn",Settings!$B$8,1)) | I7: =IF(A7="",0,G7*H7) | J7: =IF(OR(A7="",$I$17=0),"",I7/$I$17) | K7: =IF(OR(A7="",C7=0),"",D7/C7)
A8: =IF(Members!B8="","",Members!B8) | B8: =IF(A8="","",Members!E8) | C8: =IF(A8="",0,SUMIFS(Pledges!$H$5:$H$504,Pledges!$D$5:$D$504,A8)) | D8: =IF(A8="",0,SUMIFS('Work log'!$L$5:$L$1004,'Work log'!$E$5:$E$1004,A8)) | E8: =IF(A8="",0,SUMIFS('Work log'!$M$5:$M$1004,'Work log'!$E$5:$E$1004,A8)) | F8: =IF(A8="",0,SUMIFS(Contributions!$G$5:$G$304,Contributions!$B$5:$B$304,A8)) | G8: =D8+E8+F8 | H8: =IF(A8="","",IF(B8="Withdrawn",Settings!$B$8,1)) | I8: =IF(A8="",0,G8*H8) | J8: =IF(OR(A8="",$I$17=0),"",I8/$I$17) | K8: =IF(OR(A8="",C8=0),"",D8/C8)
A9: =IF(Members!B9="","",Members!B9) | B9: =IF(A9="","",Members!E9) | C9: =IF(A9="",0,SUMIFS(Pledges!$H$5:$H$504,Pledges!$D$5:$D$504,A9)) | D9: =IF(A9="",0,SUMIFS('Work log'!$L$5:$L$1004,'Work log'!$E$5:$E$1004,A9)) | E9: =IF(A9="",0,SUMIFS('Work log'!$M$5:$M$1004,'Work log'!$E$5:$E$1004,A9)) | F9: =IF(A9="",0,SUMIFS(Contributions!$G$5:$G$304,Contributions!$B$5:$B$304,A9)) | G9: =D9+E9+F9 | H9: =IF(A9="","",IF(B9="Withdrawn",Settings!$B$8,1)) | I9: =IF(A9="",0,G9*H9) | J9: =IF(OR(A9="",$I$17=0),"",I9/$I$17) | K9: =IF(OR(A9="",C9=0),"",D9/C9)
A10: =IF(Members!B10="","",Members!B10) | B10: =IF(A10="","",Members!E10) | C10: =IF(A10="",0,SUMIFS(Pledges!$H$5:$H$504,Pledges!$D$5:$D$504,A10)) | D10: =IF(A10="",0,SUMIFS('Work log'!$L$5:$L$1004,'Work log'!$E$5:$E$1004,A10)) | E10: =IF(A10="",0,SUMIFS('Work log'!$M$5:$M$1004,'Work log'!$E$5:$E$1004,A10)) | F10: =IF(A10="",0,SUMIFS(Contributions!$G$5:$G$304,Contributions!$B$5:$B$304,A10)) | G10: =D10+E10+F10 | H10: =IF(A10="","",IF(B10="Withdrawn",Settings!$B$8,1)) | I10: =IF(A10="",0,G10*H10) | J10: =IF(OR(A10="",$I$17=0),"",I10/$I$17) | K10: =IF(OR(A10="",C10=0),"",D10/C10)
A11: =IF(Members!B11="","",Members!B11) | B11: =IF(A11="","",Members!E11) | C11: =IF(A11="",0,SUMIFS(Pledges!$H$5:$H$504,Pledges!$D$5:$D$504,A11)) | D11: =IF(A11="",0,SUMIFS('Work log'!$L$5:$L$1004,'Work log'!$E$5:$E$1004,A11)) | E11: =IF(A11="",0,SUMIFS('Work log'!$M$5:$M$1004,'Work log'!$E$5:$E$1004,A11)) | F11: =IF(A11="",0,SUMIFS(Contributions!$G$5:$G$304,Contributions!$B$5:$B$304,A11)) | G11: =D11+E11+F11 | H11: =IF(A11="","",IF(B11="Withdrawn",Settings!$B$8,1)) | I11: =IF(A11="",0,G11*H11) | J11: =IF(OR(A11="",$I$17=0),"",I11/$I$17) | K11: =IF(OR(A11="",C11=0),"",D11/C11)
A12: =IF(Members!B12="","",Members!B12) | B12: =IF(A12="","",Members!E12) | C12: =IF(A12="",0,SUMIFS(Pledges!$H$5:$H$504,Pledges!$D$5:$D$504,A12)) | D12: =IF(A12="",0,SUMIFS('Work log'!$L$5:$L$1004,'Work log'!$E$5:$E$1004,A12)) | E12: =IF(A12="",0,SUMIFS('Work log'!$M$5:$M$1004,'Work log'!$E$5:$E$1004,A12)) | F12: =IF(A12="",0,SUMIFS(Contributions!$G$5:$G$304,Contributions!$B$5:$B$304,A12)) | G12: =D12+E12+F12 | H12: =IF(A12="","",IF(B12="Withdrawn",Settings!$B$8,1)) | I12: =IF(A12="",0,G12*H12) | J12: =IF(OR(A12="",$I$17=0),"",I12/$I$17) | K12: =IF(OR(A12="",C12=0),"",D12/C12)
A13: =IF(Members!B13="","",Members!B13) | B13: =IF(A13="","",Members!E13) | C13: =IF(A13="",0,SUMIFS(Pledges!$H$5:$H$504,Pledges!$D$5:$D$504,A13)) | D13: =IF(A13="",0,SUMIFS('Work log'!$L$5:$L$1004,'Work log'!$E$5:$E$1004,A13)) | E13: =IF(A13="",0,SUMIFS('Work log'!$M$5:$M$1004,'Work log'!$E$5:$E$1004,A13)) | F13: =IF(A13="",0,SUMIFS(Contributions!$G$5:$G$304,Contributions!$B$5:$B$304,A13)) | G13: =D13+E13+F13 | H13: =IF(A13="","",IF(B13="Withdrawn",Settings!$B$8,1)) | I13: =IF(A13="",0,G13*H13) | J13: =IF(OR(A13="",$I$17=0),"",I13/$I$17) | K13: =IF(OR(A13="",C13=0),"",D13/C13)
A14: =IF(Members!B14="","",Members!B14) | B14: =IF(A14="","",Members!E14) | C14: =IF(A14="",0,SUMIFS(Pledges!$H$5:$H$504,Pledges!$D$5:$D$504,A14)) | D14: =IF(A14="",0,SUMIFS('Work log'!$L$5:$L$1004,'Work log'!$E$5:$E$1004,A14)) | E14: =IF(A14="",0,SUMIFS('Work log'!$M$5:$M$1004,'Work log'!$E$5:$E$1004,A14)) | F14: =IF(A14="",0,SUMIFS(Contributions!$G$5:$G$304,Contributions!$B$5:$B$304,A14)) | G14: =D14+E14+F14 | H14: =IF(A14="","",IF(B14="Withdrawn",Settings!$B$8,1)) | I14: =IF(A14="",0,G14*H14) | J14: =IF(OR(A14="",$I$17=0),"",I14/$I$17) | K14: =IF(OR(A14="",C14=0),"",D14/C14)
A15: =IF(Members!B15="","",Members!B15) | B15: =IF(A15="","",Members!E15) | C15: =IF(A15="",0,SUMIFS(Pledges!$H$5:$H$504,Pledges!$D$5:$D$504,A15)) | D15: =IF(A15="",0,SUMIFS('Work log'!$L$5:$L$1004,'Work log'!$E$5:$E$1004,A15)) | E15: =IF(A15="",0,SUMIFS('Work log'!$M$5:$M$1004,'Work log'!$E$5:$E$1004,A15)) | F15: =IF(A15="",0,SUMIFS(Contributions!$G$5:$G$304,Contributions!$B$5:$B$304,A15)) | G15: =D15+E15+F15 | H15: =IF(A15="","",IF(B15="Withdrawn",Settings!$B$8,1)) | I15: =IF(A15="",0,G15*H15) | J15: =IF(OR(A15="",$I$17=0),"",I15/$I$17) | K15: =IF(OR(A15="",C15=0),"",D15/C15)
A16: =IF(Members!B16="","",Members!B16) | B16: =IF(A16="","",Members!E16) | C16: =IF(A16="",0,SUMIFS(Pledges!$H$5:$H$504,Pledges!$D$5:$D$504,A16)) | D16: =IF(A16="",0,SUMIFS('Work log'!$L$5:$L$1004,'Work log'!$E$5:$E$1004,A16)) | E16: =IF(A16="",0,SUMIFS('Work log'!$M$5:$M$1004,'Work log'!$E$5:$E$1004,A16)) | F16: =IF(A16="",0,SUMIFS(Contributions!$G$5:$G$304,Contributions!$B$5:$B$304,A16)) | G16: =D16+E16+F16 | H16: =IF(A16="","",IF(B16="Withdrawn",Settings!$B$8,1)) | I16: =IF(A16="",0,G16*H16) | J16: =IF(OR(A16="",$I$17=0),"",I16/$I$17) | K16: =IF(OR(A16="",C16=0),"",D16/C16)
A17: Total | C17: =SUM(C5:C16) | D17: =SUM(D5:D16) | E17: =SUM(E5:E16) | F17: =SUM(F5:F16) | G17: =SUM(G5:G16) | I17: =SUM(I5:I16) | J17: =SUM(J5:J16)
A19: Build summary
